<?xml version='1.0' encoding='utf-8'?>
<robot name="jiyuan_bilateral_bilateral">
  <link name="base_link">
    <inertial>
      <origin xyz="0.000342841578761649 0.0533737179043439 -0.00322755034160716" rpy="0 0 0" />
      <mass value="0.578447340656943" />
      <inertia ixx="0.00245194046846196" ixy="-1.92136996193314E-06" ixz="-1.37944712014845E-06" iyy="0.00268497193612229" iyz="0.000478440184651817" izz="0.0026510301534111" />
    </inertial>
    <visual>
      <origin xyz="0 0 0" rpy="0 0 0" />
      <geometry>
        <mesh filename="package://jiyuan/meshes/base_link.STL" />
      </geometry>
      <material name="">
        <color rgba="1 1 1 1" />
      </material>
    </visual>
    <collision>
      <origin xyz="0 0 0" rpy="0 0 0" />
      <geometry>
        <mesh filename="package://jiyuan/meshes/base_link.STL" />
      </geometry>
    </collision>
  </link>
  <link name="right_hip_pitch_engine_link">
    <inertial>
      <origin xyz="-0.00639528170474211 -5.28330276241918E-05 -1.32444315893138E-07" rpy="0 0 0" />
      <mass value="0.00680931690813817" />
      <inertia ixx="3.39928584447202E-06" ixy="-2.74780005767967E-12" ixz="1.29764844440883E-11" iyy="3.82287795367196E-06" iyz="-3.93183797563819E-11" izz="9.53831394208114E-07" />
    </inertial>
    <visual>
      <origin xyz="0 0 0" rpy="0 0 0" />
      <geometry>
        <mesh filename="package://jiyuan/meshes/right_hip_pitch_engine_link.STL" />
      </geometry>
      <material name="">
        <color rgba="1 1 1 1" />
      </material>
    </visual>
    <collision>
      <origin xyz="0 0 0" rpy="0 0 0" />
      <geometry>
        <mesh filename="package://jiyuan/meshes/right_hip_pitch_engine_link.STL" />
      </geometry>
    </collision>
  </link>
  <joint name="right_hip_pitch_engine_joint" type="revolute">
    <origin xyz="-0.084333154461223 2.45945382447853E-05 0" rpy="0 0 0" />
    <parent link="base_link" />
    <child link="right_hip_pitch_engine_link" />
    <axis xyz="0 0 1" />
    <limit lower="-3.14" upper="3.14" effort="100" velocity="1" />
  </joint>
  <link name="right_hip_yaw_engine_link">
    <inertial>
      <origin xyz="-0.00997581688662634 -4.91949854028881E-05 -3.35518278792401E-06" rpy="0 0 0" />
      <mass value="0.00745115887807254" />
      <inertia ixx="4.37003711979543E-06" ixy="1.54442408912393E-20" ixz="1.55388242853849E-20" iyy="1.36593231884734E-06" iyz="-1.97036141605652E-10" izz="5.12920734013458E-06" />
    </inertial>
    <visual>
      <origin xyz="0 0 0" rpy="0 0 0" />
      <geometry>
        <mesh filename="package://jiyuan/meshes/right_hip_yaw_engine_link.STL" />
      </geometry>
      <material name="">
        <color rgba="1 1 1 1" />
      </material>
    </visual>
    <collision>
      <origin xyz="0 0 0" rpy="0 0 0" />
      <geometry>
        <mesh filename="package://jiyuan/meshes/right_hip_yaw_engine_link.STL" />
      </geometry>
    </collision>
  </link>
  <joint name="right_hip_yaw_engine_joint" type="revolute">
    <origin xyz="-0.084333154461223 2.45945382447853E-05 0" rpy="0 0 0" />
    <parent link="base_link" />
    <child link="right_hip_yaw_engine_link" />
    <axis xyz="0 1 0" />
    <limit lower="-3.14" upper="3.14" effort="100" velocity="1" />
  </joint>
  <link name="right_hip_roll_link">
    <inertial>
      <origin xyz="0.0250955672145867 -0.000100584304280602 -6.72379018460021E-07" rpy="0 0 0" />
      <mass value="0.00374844887826709" />
      <inertia ixx="1.73509180930169E-07" ixy="2.26869315440614E-14" ixz="-1.348110168534E-13" iyy="5.29714495902645E-07" iyz="5.67701628384787E-10" izz="4.86108472108004E-07" />
    </inertial>
    <visual>
      <origin xyz="0 0 0" rpy="0 0 0" />
      <geometry>
        <mesh filename="package://jiyuan/meshes/right_hip_roll_link.STL" />
      </geometry>
      <material name="">
        <color rgba="0.792156862745098 0.819607843137255 0.933333333333333 1" />
      </material>
    </visual>
    <collision>
      <origin xyz="0 0 0" rpy="0 0 0" />
      <geometry>
        <mesh filename="package://jiyuan/meshes/right_hip_roll_link.STL" />
      </geometry>
    </collision>
  </link>
  <joint name="right_hip_roll_joint" type="revolute">
    <origin xyz="-0.084333154461223 2.45945382447853E-05 0" rpy="0 0 0" />
    <parent link="base_link" />
    <child link="right_hip_roll_link" />
    <axis xyz="-1 0 0" />
    <limit lower="-3.14" upper="3.14" effort="100" velocity="1" />
  </joint>
  <link name="right_hip_cube_link">
    <inertial>
      <origin xyz="0.00499999363631391 -4.91949854027494E-05 -2.68144890015451E-15" rpy="0 0 0" />
      <mass value="0.000245876972106249" />
      <inertia ixx="4.25015788197773E-09" ixy="6.85161708351657E-24" ixz="-4.41516842085342E-23" iyy="2.40441823778431E-09" iyz="-2.06386564924476E-15" izz="2.40441187048372E-09" />
    </inertial>
    <visual>
      <origin xyz="0 0 0" rpy="0 0 0" />
      <geometry>
        <mesh filename="package://jiyuan/meshes/right_hip_cube_link.STL" />
      </geometry>
      <material name="">
        <color rgba="0.792156862745098 0.819607843137255 0.933333333333333 1" />
      </material>
    </visual>
    <collision>
      <origin xyz="0 0 0" rpy="0 0 0" />
      <geometry>
        <mesh filename="package://jiyuan/meshes/right_hip_cube_link.STL" />
      </geometry>
    </collision>
  </link>
  <joint name="right_hip_cube_joint" type="revolute">
    <origin xyz="0 0 0" rpy="0 0 0" />
    <parent link="right_hip_roll_link" />
    <child link="right_hip_cube_link" />
    <axis xyz="0 0 1" />
    <limit lower="-3.14" upper="3.14" effort="100" velocity="1" />
  </joint>
  <link name="right_thigh_link">
    <inertial>
      <origin xyz="-0.0338250068183917 -0.233568091984252 -0.00694723150581045" rpy="0 0 0" />
      <mass value="0.651256730970666" />
      <inertia ixx="0.00206893634437099" ixy="0.000272110721077152" ixz="-6.12788038461608E-05" iyy="0.00177958880876041" iyz="0.000133779452072601" izz="0.00201266566655095" />
    </inertial>
    <visual>
      <origin xyz="0 0 0" rpy="0 0 0" />
      <geometry>
        <mesh filename="package://jiyuan/meshes/right_thigh_link.STL" />
      </geometry>
      <material name="">
        <color rgba="0.792156862745098 0.819607843137255 0.933333333333333 1" />
      </material>
    </visual>
    <collision>
      <origin xyz="0 0 0" rpy="0 0 0" />
      <geometry>
        <mesh filename="package://jiyuan/meshes/right_thigh_link.STL" />
      </geometry>
    </collision>
  </link>
  <joint name="right_thigh_joint" type="revolute">
    <origin xyz="0 0 0" rpy="0 0 0" />
    <parent link="right_hip_cube_link" />
    <child link="right_thigh_link" />
    <axis xyz="0 1 0" />
    <limit lower="-3.14" upper="3.14" effort="100" velocity="1" />
  </joint>
  <link name="right_shin_link">
    <inertial>
      <origin xyz="8.93525504408327E-05 -0.207812925039368 0.00356242368804441" rpy="0 0 0" />
      <mass value="0.347813967537165" />
      <inertia ixx="0.00126357262237321" ixy="-1.32038172506396E-06" ixz="-3.06631552454993E-07" iyy="0.000301407339733946" iyz="6.71088337977351E-05" izz="0.00128278527429904" />
    </inertial>
    <visual>
      <origin xyz="0 0 0" rpy="0 0 0" />
      <geometry>
        <mesh filename="package://jiyuan/meshes/right_shin_link.STL" />
      </geometry>
      <material name="">
        <color rgba="0.792156862745098 0.819607843137255 0.933333333333333 1" />
      </material>
    </visual>
    <collision>
      <origin xyz="0 0 0" rpy="0 0 0" />
      <geometry>
        <mesh filename="package://jiyuan/meshes/right_shin_link.STL" />
      </geometry>
    </collision>
  </link>
  <joint name="right_knee_joint" type="revolute">
    <origin xyz="-0.025666845538777 -0.429824594538245 -0.0115000000000049" rpy="0 0 0" />
    <parent link="right_thigh_link" />
    <child link="right_shin_link" />
    <axis xyz="1 0 0" />
    <limit lower="-3.14" upper="3.14" effort="100" velocity="1" />
  </joint>
  <link name="right_ankle_cube_link">
    <inertial>
      <origin xyz="-0.025670003801888 -0.88668648907311 0.00800489820165312" rpy="0 0 0" />
      <mass value="0.000189328304341638" />
      <inertia ixx="1.15268360237197E-09" ixy="-8.75476909303627E-33" ixz="-2.1460399983049E-15" iyy="1.81031848738358E-09" iyz="-4.36007820098051E-26" izz="1.15268986006577E-09" />
    </inertial>
    <visual>
      <origin xyz="0 0 0" rpy="0 0 0" />
      <geometry>
        <mesh filename="package://jiyuan/meshes/right_ankle_cube_link.STL" />
      </geometry>
      <material name="">
        <color rgba="0.792156862745098 0.819607843137255 0.933333333333333 1" />
      </material>
    </visual>
    <collision>
      <origin xyz="0 0 0" rpy="0 0 0" />
      <geometry>
        <mesh filename="package://jiyuan/meshes/right_ankle_cube_link.STL" />
      </geometry>
    </collision>
  </link>
  <joint name="right_ankle_cube_joint" type="revolute">
    <origin xyz="0.025666845538777 0.429824594538245 0.0115000000000049" rpy="0 0 0" />
    <parent link="right_shin_link" />
    <child link="right_ankle_cube_link" />
    <axis xyz="0 0 1" />
    <limit lower="-3.14" upper="3.14" effort="100" velocity="1" />
  </joint>
  <link name="right_ankle_axle_link">
    <inertial>
      <origin xyz="-6.92213906759859E-05 -0.0250851665328068 7.51570114941435E-05" rpy="0 0 0" />
      <mass value="0.00188539443116976" />
      <inertia ixx="3.40886776481147E-07" ixy="-5.50460625860004E-14" ixz="-1.93998889501305E-10" iyy="1.59411257248695E-08" iyz="-1.08549833532568E-15" izz="3.43001179235715E-07" />
    </inertial>
    <visual>
      <origin xyz="0 0 0" rpy="0 0 0" />
      <geometry>
        <mesh filename="package://jiyuan/meshes/right_ankle_axle_link.STL" />
      </geometry>
      <material name="">
        <color rgba="0.792156862745098 0.819607843137255 0.933333333333333 1" />
      </material>
    </visual>
    <collision>
      <origin xyz="0 0 0" rpy="0 0 0" />
      <geometry>
        <mesh filename="package://jiyuan/meshes/right_ankle_axle_link.STL" />
      </geometry>
    </collision>
  </link>
  <joint name="right_ankle_axle_joint" type="revolute">
    <origin xyz="-0.0256700103430628 -0.886686499663044 0.00800489064197998" rpy="0 0 0" />
    <parent link="right_ankle_cube_link" />
    <child link="right_ankle_axle_link" />
    <axis xyz="1 0 0" />
    <limit lower="-3.14" upper="3.14" effort="100" velocity="1" />
  </joint>
  <link name="right_foot_link">
    <inertial>
      <origin xyz="-0.00433742702605386 -0.0410689912642686 0.0153050659615987" rpy="0 0 0" />
      <mass value="0.138474623900111" />
      <inertia ixx="0.000249638228785326" ixy="-7.51556284441056E-08" ixz="6.92688285527476E-08" iyy="0.000245679101559375" iyz="-9.50093987655504E-06" izz="0.000115983156725437" />
    </inertial>
    <visual>
      <origin xyz="0 0 0" rpy="0 0 0" />
      <geometry>
        <mesh filename="package://jiyuan/meshes/right_foot_link.STL" />
      </geometry>
      <material name="">
        <color rgba="0.792156862745098 0.819607843137255 0.933333333333333 1" />
      </material>
    </visual>
    <collision>
      <origin xyz="0 0 0" rpy="0 0 0" />
      <geometry>
        <mesh filename="package://jiyuan/meshes/right_foot_link.STL" />
      </geometry>
    </collision>
  </link>
  <joint name="right_foot_joint" type="revolute">
    <origin xyz="0 -0.0147499860831098 0" rpy="0 0 0" />
    <parent link="right_ankle_axle_link" />
    <child link="right_foot_link" />
    <axis xyz="0 -1 0" />
    <limit lower="-3.14" upper="3.14" effort="100" velocity="1" />
  </joint>
  <link name="right_toe_link">
    <inertial>
      <origin xyz="-0.000572444640377659 0.00216340409996052 0.021116546041816" rpy="0 0 0" />
      <mass value="0.0528822247684903" />
      <inertia ixx="3.25175653226149E-05" ixy="-1.62060260555305E-08" ixz="-8.56599509772465E-07" iyy="5.35566607091479E-05" iyz="-5.09324728976432E-08" izz="3.36873480136063E-05" />
    </inertial>
    <visual>
      <origin xyz="0 0 0" rpy="0 0 0" />
      <geometry>
        <mesh filename="package://jiyuan/meshes/right_toe_link.STL" />
      </geometry>
      <material name="">
        <color rgba="0.792156862745098 0.819607843137255 0.933333333333333 1" />
      </material>
    </visual>
    <collision>
      <origin xyz="0 0 0" rpy="0 0 0" />
      <geometry>
        <mesh filename="package://jiyuan/meshes/right_toe_link.STL" />
      </geometry>
    </collision>
  </link>
  <joint name="right_toe_joint" type="revolute">
    <origin xyz="0.000499999710812979 -0.0646056174661427 0.105614593490204" rpy="0 0 0" />
    <parent link="right_foot_link" />
    <child link="right_toe_link" />
    <axis xyz="1 0 0" />
    <limit lower="-3.14" upper="3.14" effort="100" velocity="1" />
  </joint>
  <link name="spine_001_axle_link">
    <inertial>
      <origin xyz="-6.81364790209148E-05 -0.0166556791326088 -8.82627506705036E-05" rpy="0 0 0" />
      <mass value="0.00172774341614448" />
      <inertia ixx="3.37594632257428E-07" ixy="-4.42992152760797E-14" ixz="6.34127654350488E-10" iyy="1.31803592087778E-08" iyz="4.34897905557677E-14" izz="3.40137650046851E-07" />
    </inertial>
    <visual>
      <origin xyz="0 0 0" rpy="0 0 0" />
      <geometry>
        <mesh filename="package://jiyuan/meshes/spine_001_axle_link.STL" />
      </geometry>
      <material name="">
        <color rgba="0.792156862745098 0.819607843137255 0.933333333333333 1" />
      </material>
    </visual>
    <collision>
      <origin xyz="0 0 0" rpy="0 0 0" />
      <geometry>
        <mesh filename="package://jiyuan/meshes/spine_001_axle_link.STL" />
      </geometry>
    </collision>
  </link>
  <joint name="base_joint" type="revolute">
    <origin xyz="0 0.087689 0.002418" rpy="0.2618 0.00052789 0.00014145" />
    <parent link="base_link" />
    <child link="spine_001_axle_link" />
    <axis xyz="0 1 0" />
    <limit lower="-3.14" upper="3.14" effort="100" velocity="1" />
  </joint>
  <link name="spine_001_cube_link">
    <inertial>
      <origin xyz="1.51788304147971E-17 -3.32695611338085E-09 -8.67361737988404E-18" rpy="0 0 0" />
      <mass value="0.000189328304341632" />
      <inertia ixx="1.15268986006576E-09" ixy="3.52197995188594E-25" ixz="2.14603999937639E-15" iyy="1.81031848738356E-09" iyz="1.09859925104699E-25" izz="1.15268360237195E-09" />
    </inertial>
    <visual>
      <origin xyz="0 0 0" rpy="0 0 0" />
      <geometry>
        <mesh filename="package://jiyuan/meshes/spine_001_cube_link.STL" />
      </geometry>
      <material name="">
        <color rgba="0.792156862745098 0.819607843137255 0.933333333333333 1" />
      </material>
    </visual>
    <collision>
      <origin xyz="0 0 0" rpy="0 0 0" />
      <geometry>
        <mesh filename="package://jiyuan/meshes/spine_001_cube_link.STL" />
      </geometry>
    </collision>
  </link>
  <joint name="spine_001_axle_joint" type="revolute">
    <origin xyz="0 0.011 0" rpy="-0.344154933334362 0.174881984566998 0" />
    <parent link="spine_001_axle_link" />
    <child link="spine_001_cube_link" />
    <axis xyz="-1 0 0" />
    <limit lower="-3.14" upper="3.14" effort="100" velocity="1" />
  </joint>
  <link name="spine_001_link">
    <inertial>
      <origin xyz="0.00477881144454462 0.0803583169100199 3.47839628433988E-06" rpy="0 0 0" />
      <mass value="0.0320197009924435" />
      <inertia ixx="3.92472750224256E-06" ixy="6.40845526362862E-08" ixz="-1.94138164905801E-09" iyy="5.00674291577168E-06" iyz="6.52922320204402E-10" izz="3.92225457418834E-06" />
    </inertial>
    <visual>
      <origin xyz="0 0 0" rpy="0 0 0" />
      <geometry>
        <mesh filename="package://jiyuan/meshes/spine_001_link.STL" />
      </geometry>
      <material name="">
        <color rgba="0.792156862745098 0.819607843137255 0.933333333333333 1" />
      </material>
    </visual>
    <collision>
      <origin xyz="0 0 0" rpy="0 0 0" />
      <geometry>
        <mesh filename="package://jiyuan/meshes/spine_001_link.STL" />
      </geometry>
    </collision>
  </link>
  <joint name="spine_001_cube_joint" type="revolute">
    <origin xyz="0 0 0" rpy="0 0 0" />
    <parent link="spine_001_cube_link" />
    <child link="spine_001_link" />
    <axis xyz="0 0 1" />
    <limit lower="-3.14" upper="3.14" effort="100" velocity="1" />
  </joint>
  <link name="spine_002_axle_link">
    <inertial>
      <origin xyz="-8.5293056884324E-07 0.00445734981920043 4.63084204836706E-09" rpy="0 0 0" />
      <mass value="0.000510082145710689" />
      <inertia ixx="9.61926882973004E-09" ixy="4.36960296659341E-14" ixz="7.25336258511661E-11" iyy="9.66869078023053E-09" iyz="-2.58349805821469E-15" izz="1.22172647528038E-08" />
    </inertial>
    <visual>
      <origin xyz="0 0 0" rpy="0 0 0" />
      <geometry>
        <mesh filename="package://jiyuan/meshes/spine_002_axle_link.STL" />
      </geometry>
      <material name="">
        <color rgba="0.792156862745098 0.819607843137255 0.933333333333333 1" />
      </material>
    </visual>
    <collision>
      <origin xyz="0 0 0" rpy="0 0 0" />
      <geometry>
        <mesh filename="package://jiyuan/meshes/spine_002_axle_link.STL" />
      </geometry>
    </collision>
  </link>
  <joint name="spine_001_joint" type="revolute">
    <origin xyz="0.00670068441639467 0.112400448523802 0" rpy="3.10340201864658E-05 -0.164530504019474 -0.0597333970241516" />
    <parent link="spine_001_link" />
    <child link="spine_002_axle_link" />
    <axis xyz="-0.000186916583478837 0.999999982531095 0" />
    <limit lower="-3.14" upper="3.14" effort="100" velocity="1" />
  </joint>
  <link name="spine_002_cube_link">
    <inertial>
      <origin xyz="-7.88528636374956E-12 -3.32694677362966E-09 -2.08166817117217E-17" rpy="0 0 0" />
      <mass value="0.000189328304341632" />
      <inertia ixx="1.15269355427671E-09" ixy="1.55865494430096E-12" ixz="2.14603397213778E-15" iyy="1.8103147931726E-09" iyz="-5.08637466127586E-18" izz="1.15268360237194E-09" />
    </inertial>
    <visual>
      <origin xyz="0 0 0" rpy="0 0 0" />
      <geometry>
        <mesh filename="package://jiyuan/meshes/spine_002_cube_link.STL" />
      </geometry>
      <material name="">
        <color rgba="0.792156862745098 0.819607843137255 0.933333333333333 1" />
      </material>
    </visual>
    <collision>
      <origin xyz="0 0 0" rpy="0 0 0" />
      <geometry>
        <mesh filename="package://jiyuan/meshes/spine_002_cube_link.STL" />
      </geometry>
    </collision>
  </link>
  <joint name="spine_002_axle_join" type="revolute">
    <origin xyz="0 0.0109999998078421 0" rpy="-0.17440079274189 0.0283053809155349 0.00252199483425913" />
    <parent link="spine_002_axle_link" />
    <child link="spine_002_cube_link" />
    <axis xyz="0.99999719125963 -0.00237012085153487 0" />
    <limit lower="-3.14" upper="3.14" effort="100" velocity="1" />
  </joint>
  <link name="spine_002_link">
    <inertial>
      <origin xyz="0.000801973808676076 0.0795245678000815 0.000127820576549247" rpy="0 0 0" />
      <mass value="0.0309518546203202" />
      <inertia ixx="3.72797062909746E-06" ixy="-2.81832386956808E-08" ixz="-4.42587281548403E-08" iyy="4.75187414875097E-06" iyz="-2.12158099072287E-08" izz="3.77640370140202E-06" />
    </inertial>
    <visual>
      <origin xyz="0 0 0" rpy="0 0 0" />
      <geometry>
        <mesh filename="package://jiyuan/meshes/spine_002_link.STL" />
      </geometry>
      <material name="">
        <color rgba="0.792156862745098 0.819607843137255 0.933333333333333 1" />
      </material>
    </visual>
    <collision>
      <origin xyz="0 0 0" rpy="0 0 0" />
      <geometry>
        <mesh filename="package://jiyuan/meshes/spine_002_link.STL" />
      </geometry>
    </collision>
  </link>
  <joint name="spine_002_cube_join" type="revolute">
    <origin xyz="0 0 0" rpy="0 0 0" />
    <parent link="spine_002_cube_link" />
    <child link="spine_002_link" />
    <axis xyz="0 0 -1" />
    <limit lower="-3.14" upper="3.14" effort="100" velocity="1" />
  </joint>
  <link name="spine_003_axle_link">
    <inertial>
      <origin xyz="-1.2343072277775E-06 0.00445735132318464 1.25901573819198E-08" rpy="0 0 0" />
      <mass value="0.000510082296418304" />
      <inertia ixx="9.79300454363617E-09" ixy="7.40587106164338E-14" ixz="6.53013199671426E-10" iyy="9.66869325506815E-09" iyz="1.37516106939874E-13" izz="1.20435450931177E-08" />
    </inertial>
    <visual>
      <origin xyz="0 0 0" rpy="0 0 0" />
      <geometry>
        <mesh filename="package://jiyuan/meshes/spine_003_axle_link.STL" />
      </geometry>
      <material name="">
        <color rgba="0.792156862745098 0.819607843137255 0.933333333333333 1" />
      </material>
    </visual>
    <collision>
      <origin xyz="0 0 0" rpy="0 0 0" />
      <geometry>
        <mesh filename="package://jiyuan/meshes/spine_003_axle_link.STL" />
      </geometry>
    </collision>
  </link>
  <joint name="spine_002_joint" type="revolute">
    <origin xyz="0.000806435919506334 0.111797091469804 0" rpy="0 -0.0274704855817947 -0.00748662087643142" />
    <parent link="spine_002_link" />
    <child link="spine_003_axle_link" />
    <axis xyz="0.000273253759191587 -0.999999962666191 0" />
    <limit lower="-3.14" upper="3.14" effort="100" velocity="1" />
  </joint>
  <link name="spine_003_cube_link">
    <inertial>
      <origin xyz="2.24132802595367E-10 3.31939192799169E-09 3.46944695195361E-17" rpy="0 0 0" />
      <mass value="0.000189328304341632" />
      <inertia ixx="1.15567454139414E-09" ixy="4.42029813738197E-11" ixz="-2.14116450403375E-15" iyy="1.80733380605517E-09" iyz="1.44576079131681E-16" izz="1.15268360237194E-09" />
    </inertial>
    <visual>
      <origin xyz="0 0 0" rpy="0 0 0" />
      <geometry>
        <mesh filename="package://jiyuan/meshes/spine_003_cube_link.STL" />
      </geometry>
      <material name="">
        <color rgba="0.792156862745098 0.819607843137255 0.933333333333333 1" />
      </material>
    </visual>
    <collision>
      <origin xyz="0 0 0" rpy="0 0 0" />
      <geometry>
        <mesh filename="package://jiyuan/meshes/spine_003_cube_link.STL" />
      </geometry>
    </collision>
  </link>
  <joint name="spine_003_axle_joint" type="revolute">
    <origin xyz="0 0.0109999995893339 0" rpy="0.186095390069988 0.251012260294841 0.0688886558053852" />
    <parent link="spine_003_axle_link" />
    <child link="spine_003_cube_link" />
    <axis xyz="0.997728143633419 -0.0673687717107211 0" />
    <limit lower="-3.14" upper="3.14" effort="100" velocity="1" />
  </joint>
  <link name="spine_003_link">
    <inertial>
      <origin xyz="0.00177134494191662 0.0802385750035131 -9.46707370307054E-06" rpy="0 0 0" />
      <mass value="0.0320197010019784" />
      <inertia ixx="3.92193150802631E-06" ixy="2.35593182664786E-08" ixz="-2.21265108146424E-09" iyy="5.01001542027223E-06" iyz="5.22385563303224E-10" izz="3.92177806466506E-06" />
    </inertial>
    <visual>
      <origin xyz="0 0 0" rpy="0 0 0" />
      <geometry>
        <mesh filename="package://jiyuan/meshes/spine_003_link.STL" />
      </geometry>
      <material name="">
        <color rgba="0.792156862745098 0.819607843137255 0.933333333333333 1" />
      </material>
    </visual>
    <collision>
      <origin xyz="0 0 0" rpy="0 0 0" />
      <geometry>
        <mesh filename="package://jiyuan/meshes/spine_003_link.STL" />
      </geometry>
    </collision>
  </link>
  <joint name="spine_003_cube_joint" type="revolute">
    <origin xyz="0 0 0" rpy="0 0 0" />
    <parent link="spine_003_cube_link" />
    <child link="spine_003_link" />
    <axis xyz="0 0 1" />
    <limit lower="-3.14" upper="3.14" effort="100" velocity="1" />
  </joint>
  <link name="spine_004_axle_link">
    <inertial>
      <origin xyz="-8.1370475639004E-07 0.00445734940001424 2.72269845558171E-11" rpy="0 0 0" />
      <mass value="0.000510082123516246" />
      <inertia ixx="9.73607642682156E-09" ixy="-4.16691187289795E-14" ixz="5.43222243324636E-10" iyy="9.66869022459252E-09" iyz="9.58488402690517E-14" izz="1.21004535832996E-08" />
    </inertial>
    <visual>
      <origin xyz="0 0 0" rpy="0 0 0" />
      <geometry>
        <mesh filename="package://jiyuan/meshes/spine_004_axle_link.STL" />
      </geometry>
      <material name="">
        <color rgba="0.792156862745098 0.819607843137255 0.933333333333333 1" />
      </material>
    </visual>
    <collision>
      <origin xyz="0 0 0" rpy="0 0 0" />
      <geometry>
        <mesh filename="package://jiyuan/meshes/spine_004_axle_link.STL" />
      </geometry>
    </collision>
  </link>
  <joint name="spine_003_joint" type="revolute">
    <origin xyz="0.00250119688024906 0.112272142645293 0" rpy="4.95430163599117E-05 -0.259096323257594 -0.0224676694074587" />
    <parent link="spine_003_link" />
    <child link="spine_004_axle_link" />
    <axis xyz="-0.000186916583478925 0.999999982531095 0" />
    <limit lower="-3.14" upper="3.14" effort="100" velocity="1" />
  </joint>
  <link name="spine_004_cube_link">
    <inertial>
      <origin xyz="-6.70852193240812E-11 -3.32450422746433E-09 9.58594315036976E-13" rpy="0 0 0" />
      <mass value="0.000189328304341632" />
      <inertia ixx="1.15292131882603E-09" ixy="1.23353286800362E-11" ixz="2.14566230487006E-15" iyy="1.81008702862328E-09" iyz="-4.02609733996255E-17" izz="1.15268360237194E-09" />
    </inertial>
    <visual>
      <origin xyz="0 0 0" rpy="0 0 0" />
      <geometry>
        <mesh filename="package://jiyuan/meshes/spine_004_cube_link.STL" />
      </geometry>
      <material name="">
        <color rgba="0.792156862745098 0.819607843137255 0.933333333333333 1" />
      </material>
    </visual>
    <collision>
      <origin xyz="0 0 0" rpy="0 0 0" />
      <geometry>
        <mesh filename="package://jiyuan/meshes/spine_004_cube_link.STL" />
      </geometry>
    </collision>
  </link>
  <joint name="spine_004_axle_joint" type="revolute">
    <origin xyz="0 0.0109999998063652 0" rpy="0.259937971789517 0.210585098557286 0.0187470971171111" />
    <parent link="spine_004_axle_link" />
    <child link="spine_004_cube_link" />
    <axis xyz="-0.999824004673546 0.0187605884383361 0" />
    <limit lower="-3.14" upper="3.14" effort="100" velocity="1" />
  </joint>
  <link name="spine_004_link">
    <inertial>
      <origin xyz="-0.00238122688957205 0.0648563004557857 3.61472670068197E-05" rpy="0 0 0" />
      <mass value="0.0123462395112595" />
      <inertia ixx="1.24638411276011E-06" ixy="2.30755786575525E-08" ixz="7.22859540584703E-10" iyy="6.16681440516875E-07" iyz="2.65703348308066E-11" izz="1.24420291683789E-06" />
    </inertial>
    <visual>
      <origin xyz="0 0 0" rpy="0 0 0" />
      <geometry>
        <mesh filename="package://jiyuan/meshes/spine_004_link.STL" />
      </geometry>
      <material name="">
        <color rgba="0.792156862745098 0.819607843137255 0.933333333333333 1" />
      </material>
    </visual>
    <collision>
      <origin xyz="0 0 0" rpy="0 0 0" />
      <geometry>
        <mesh filename="package://jiyuan/meshes/spine_004_link.STL" />
      </geometry>
    </collision>
  </link>
  <joint name="spine_004_cube_joint" type="revolute">
    <origin xyz="0 0 0" rpy="0 0 0" />
    <parent link="spine_004_cube_link" />
    <child link="spine_004_link" />
    <axis xyz="0 0 1" />
    <limit lower="-3.14" upper="3.14" effort="100" velocity="1" />
  </joint>
  <link name="neck_axle_link">
    <inertial>
      <origin xyz="1.97342957947155E-10 3.32109806322478E-09 9.71445146547012E-17" rpy="0 0 0" />
      <mass value="0.000189328304341631" />
      <inertia ixx="1.15500369334742E-09" ixy="3.89395580407495E-11" ixz="-2.14226130109088E-15" iyy="1.80800465410189E-09" iyz="1.27295628485341E-16" izz="1.15268360237194E-09" />
    </inertial>
    <visual>
      <origin xyz="0 0 0" rpy="0 0 0" />
      <geometry>
        <mesh filename="package://jiyuan/meshes/neck_axle_link.STL" />
      </geometry>
      <material name="">
        <color rgba="0.792156862745098 0.819607843137255 0.933333333333333 1" />
      </material>
    </visual>
    <collision>
      <origin xyz="0 0 0" rpy="0 0 0" />
      <geometry>
        <mesh filename="package://jiyuan/meshes/neck_axle_link.STL" />
      </geometry>
    </collision>
  </link>
  <joint name="spine_004_joint" type="revolute">
    <origin xyz="-0.00474688798162995 0.129713172249461 0" rpy="-0.0184410969908424 -0.435431971027392 0.0802758501201312" />
    <parent link="spine_004_link" />
    <child link="neck_axle_link" />
    <axis xyz="0 0 1" />
    <limit lower="-3.14" upper="3.14" effort="100" velocity="1" />
  </joint>
  <link name="neck_cube_link">
    <inertial>
      <origin xyz="7.32482458266021E-05 -0.0033443104319979 -8.44870465414316E-05" rpy="0 0 0" />
      <mass value="0.00172774344297369" />
      <inertia ixx="3.37669619299395E-07" ixy="4.74595439912183E-11" ixz="-7.6630048630174E-10" iyy="1.31803653827576E-08" iyz="-9.10725093518117E-14" izz="3.40062652906258E-07" />
    </inertial>
    <visual>
      <origin xyz="0 0 0" rpy="0 0 0" />
      <geometry>
        <mesh filename="package://jiyuan/meshes/neck_cube_link.STL" />
      </geometry>
      <material name="">
        <color rgba="0.792156862745098 0.819607843137255 0.933333333333333 1" />
      </material>
    </visual>
    <collision>
      <origin xyz="0 0 0" rpy="0 0 0" />
      <geometry>
        <mesh filename="package://jiyuan/meshes/neck_cube_link.STL" />
      </geometry>
    </collision>
  </link>
  <joint name="neck_axle_joint" type="revolute">
    <origin xyz="0.0018322 0.030834 0.0026322" rpy="0.087233 0.22756 -0.039767" />
    <parent link="neck_axle_link" />
    <child link="neck_cube_link" />
    <axis xyz="0.97403 0.00014263 0.22641" />
    <limit lower="-3.14" upper="3.14" effort="100" velocity="1" />
  </joint>
  <link name="neck_link">
    <inertial>
      <origin xyz="1.44463327725996E-06 -0.00976336445340054 -2.96557468024983E-05" rpy="0 0 0" />
      <mass value="0.0140124948869863" />
      <inertia ixx="1.70656929568422E-06" ixy="-1.2506766612499E-10" ixz="1.0291412265966E-13" iyy="2.55846558262143E-06" iyz="-9.83384498834848E-11" izz="1.71196954793651E-06" />
    </inertial>
    <visual>
      <origin xyz="0 0 0" rpy="0 0 0" />
      <geometry>
        <mesh filename="package://jiyuan/meshes/neck_link.STL" />
      </geometry>
      <material name="">
        <color rgba="0.792156862745098 0.819607843137255 0.933333333333333 1" />
      </material>
    </visual>
    <collision>
      <origin xyz="0 0 0" rpy="0 0 0" />
      <geometry>
        <mesh filename="package://jiyuan/meshes/neck_link.STL" />
      </geometry>
    </collision>
  </link>
  <joint name="neck_joint" type="revolute">
    <origin xyz="0 0 0" rpy="0 0 0" />
    <parent link="neck_cube_link" />
    <child link="neck_link" />
    <axis xyz="0.00014644 -1 0" />
    <limit lower="-3.14" upper="3.14" effort="100" velocity="1" />
  </joint>
  <link name="right_branch_link">
    <inertial>
      <origin xyz="0.0342087441276741 -0.00176734097123937 -0.00120947727238396" rpy="0 0 0" />
      <mass value="0.013497890740739" />
      <inertia ixx="1.2926414536493E-06" ixy="5.38399776707783E-08" ixz="4.32856935211769E-08" iyy="1.06891317628328E-06" iyz="3.95744816457389E-09" izz="1.75257133082468E-06" />
    </inertial>
    <visual>
      <origin xyz="0 0 0" rpy="0 0 0" />
      <geometry>
        <mesh filename="package://jiyuan/meshes/right_branch_link.STL" />
      </geometry>
      <material name="">
        <color rgba="0.792156862745098 0.819607843137255 0.933333333333333 1" />
      </material>
    </visual>
    <collision>
      <origin xyz="0 0 0" rpy="0 0 0" />
      <geometry>
        <mesh filename="package://jiyuan/meshes/right_branch_link.STL" />
      </geometry>
    </collision>
  </link>
  <joint name="right_branch_link" type="fixed">
    <origin xyz="-0.0772640532330563 0.102209980220283 0.00749936807653298" rpy="3.16095910023056E-05 -0.114736944872298 -0.00748936555497514" />
    <parent link="spine_002_link" />
    <child link="right_branch_link" />
    <axis xyz="0 0 0" />
    <limit lower="-3.14" upper="3.14" effort="100" velocity="1" />
  </joint>
  <link name="right_spine_003_link">
    <inertial>
      <origin xyz="0.00036404463207966 0.0420089912020032 -0.0225452756157186" rpy="0 0 0" />
      <mass value="0.0192570395361066" />
      <inertia ixx="3.29487915932372E-06" ixy="-5.96656270484953E-08" ixz="2.76839158630015E-07" iyy="2.37144676466391E-06" iyz="3.13580776458497E-07" izz="2.15117263561911E-06" />
    </inertial>
    <visual>
      <origin xyz="0 0 0" rpy="0 0 0" />
      <geometry>
        <mesh filename="package://jiyuan/meshes/right_spine_003_link.STL" />
      </geometry>
      <material name="">
        <color rgba="0.792156862745098 0.819607843137255 0.933333333333333 0.25" />
      </material>
    </visual>
    <collision>
      <origin xyz="0 0 0" rpy="0 0 0" />
      <geometry>
        <mesh filename="package://jiyuan/meshes/right_spine_003_link.STL" />
      </geometry>
    </collision>
  </link>
  <joint name="right_spine_002_joint" type="revolute">
    <origin xyz="0 0 0" rpy="0 0 0" />
    <parent link="right_branch_link" />
    <child link="right_spine_003_link" />
    <axis xyz="0.000274286186586446 -0.999999962383543 0" />
    <limit lower="-3.14" upper="3.14" effort="100" velocity="1" />
  </joint>
  <link name="right_spine_004_ground_link">
    <inertial>
      <origin xyz="0.0334438419965927 0.0335246343121994 0.025836416760253" rpy="0 0 0" />
      <mass value="0.0371077097805639" />
      <inertia ixx="1.15914902522178E-05" ixy="-1.87344982433402E-08" ixz="-4.94055284300337E-07" iyy="1.17589174084433E-05" iyz="-1.04248798188576E-08" izz="1.87631928022744E-05" />
    </inertial>
    <visual>
      <origin xyz="0 0 0" rpy="0 0 0" />
      <geometry>
        <mesh filename="package://jiyuan/meshes/right_spine_004_ground_link.STL" />
      </geometry>
      <material name="">
        <color rgba="0.792156862745098 0.819607843137255 0.933333333333333 1" />
      </material>
    </visual>
    <collision>
      <origin xyz="0 0 0" rpy="0 0 0" />
      <geometry>
        <mesh filename="package://jiyuan/meshes/right_spine_004_ground_link.STL" />
      </geometry>
    </collision>
  </link>
  <joint name="right_spine_003_joint" type="revolute">
    <origin xyz="-0.00410736211631267 0.072996321531915 -0.0467839448006484" rpy="0 -1.48365130116614 0.000274286189964258" />
    <parent link="right_spine_003_link" />
    <child link="right_spine_004_ground_link" />
    <axis xyz="-1 0 0" />
    <limit lower="-3.14" upper="3.14" effort="100" velocity="1" />
  </joint>
  <link name="right_spine_004_link">
    <inertial>
      <origin xyz="0.028182942237352 8.13448473200862E-05 2.7605138357284E-06" rpy="0 0 0" />
      <mass value="0.00196590214384828" />
      <inertia ixx="2.04393171947593E-08" ixy="1.45941256926745E-10" ixz="2.98882648257208E-10" iyy="3.48329498920359E-07" iyz="6.34072572822225E-10" izz="3.5162747886882E-07" />
    </inertial>
    <visual>
      <origin xyz="0 0 0" rpy="0 0 0" />
      <geometry>
        <mesh filename="package://jiyuan/meshes/right_spine_004_link.STL" />
      </geometry>
      <material name="">
        <color rgba="0.792156862745098 0.819607843137255 0.933333333333333 1" />
      </material>
    </visual>
    <collision>
      <origin xyz="0 0 0" rpy="0 0 0" />
      <geometry>
        <mesh filename="package://jiyuan/meshes/right_spine_004_link.STL" />
      </geometry>
    </collision>
  </link>
  <joint name="right_spine_004_ground_joint" type="revolute">
    <origin xyz="0.0432453683180946 0.0420609379831153 0.0515775502791956" rpy="-0.398518691440589 1.5703508296409 -0.660318062648173" />
    <parent link="right_spine_004_ground_link" />
    <child link="right_spine_004_link" />
    <axis xyz="0.999999495252397 -0.000443611072507391 -0.000901501063456533" />
    <limit lower="-3.14" upper="3.14" effort="100" velocity="1" />
  </joint>
  <link name="right_shoulder_link">
    <inertial>
      <origin xyz="4.60695540049905E-09 -1.3096792217393E-07 1.04989524490895E-07" rpy="0 0 0" />
      <mass value="5.46299456939302E-05" />
      <inertia ixx="3.36280041911811E-10" ixy="-5.21892557811385E-16" ixz="-3.92534891888924E-14" iyy="2.67929781003683E-10" iyz="1.55043618776817E-15" izz="2.67928900864954E-10" />
    </inertial>
    <visual>
      <origin xyz="0 0 0" rpy="0 0 0" />
      <geometry>
        <mesh filename="package://jiyuan/meshes/right_shoulder_link.STL" />
      </geometry>
      <material name="">
        <color rgba="0.792156862745098 0.819607843137255 0.933333333333333 1" />
      </material>
    </visual>
    <collision>
      <origin xyz="0 0 0" rpy="0 0 0" />
      <geometry>
        <mesh filename="package://jiyuan/meshes/right_shoulder_link.STL" />
      </geometry>
    </collision>
  </link>
  <joint name="right_spine_004_joint" type="revolute">
    <origin xyz="0 0 0" rpy="0 0 0" />
    <parent link="right_spine_004_link" />
    <child link="right_shoulder_link" />
    <axis xyz="0.000859407421352749 -0.0871557532121165 0.996194326474967" />
    <limit lower="-3.14" upper="3.14" effort="100" velocity="1" />
  </joint>
  <link name="right_arm_link">
    <inertial>
      <origin xyz="-0.0452987392277859 -0.0797744953070252 0.0108548928586347" rpy="0 0 0" />
      <mass value="0.0463841814445341" />
      <inertia ixx="2.78725979874452E-05" ixy="-4.19823686112728E-07" ixz="9.55350276886978E-08" iyy="6.10545701242481E-06" iyz="3.31966464599818E-06" izz="2.78003362567239E-05" />
    </inertial>
    <visual>
      <origin xyz="0 0 0" rpy="0 0 0" />
      <geometry>
        <mesh filename="package://jiyuan/meshes/right_arm_link.STL" />
      </geometry>
      <material name="">
        <color rgba="0.792156862745098 0.819607843137255 0.933333333333333 1" />
      </material>
    </visual>
    <collision>
      <origin xyz="0 0 0" rpy="0 0 0" />
      <geometry>
        <mesh filename="package://jiyuan/meshes/right_arm_link.STL" />
      </geometry>
    </collision>
  </link>
  <joint name="right_shoulder_joint" type="revolute">
    <origin xyz="0 0 0" rpy="0 0 0" />
    <parent link="right_shoulder_link" />
    <child link="right_arm_link" />
    <axis xyz="0.000859407421352749 -0.0871557532121165 0.996194326474967" />
    <limit lower="-3.14" upper="3.14" effort="100" velocity="1" />
  </joint>
  <link name="right_forearm_link">
    <inertial>
      <origin xyz="-0.000155041944261053 -0.140426426569951 0.0644320441565459" rpy="0 0 0" />
      <mass value="0.0295290267369982" />
      <inertia ixx="1.2939795738133E-05" ixy="-2.15707921034777E-10" ixz="8.17675472287479E-11" iyy="4.84789752124762E-06" iyz="3.71681839138466E-06" izz="1.1064910717755E-05" />
    </inertial>
    <visual>
      <origin xyz="0 0 0" rpy="0 0 0" />
      <geometry>
        <mesh filename="package://jiyuan/meshes/right_forearm_link.STL" />
      </geometry>
      <material name="">
        <color rgba="1 1 1 1" />
      </material>
    </visual>
    <collision>
      <origin xyz="0 0 0" rpy="0 0 0" />
      <geometry>
        <mesh filename="package://jiyuan/meshes/right_forearm_link.STL" />
      </geometry>
    </collision>
  </link>
  <joint name="right_elbow_joint" type="revolute">
    <origin xyz="-0.0456518822542674 -0.198226035200409 0.0273940850548131" rpy="-0.13165218489478 0.173467112582246 -0.0249549558994513" />
    <parent link="right_arm_link" />
    <child link="right_forearm_link" />
    <axis xyz="-1 0 0" />
    <limit lower="-3.14" upper="3.14" effort="100" velocity="1" />
  </joint>
  <link name="right_wrist_link">
    <inertial>
      <origin xyz="-2.77555756156289E-17 -0.0299999966730439 -5.55111512312578E-17" rpy="0 0 0" />
      <mass value="0.000189328304341632" />
      <inertia ixx="1.15268360237195E-09" ixy="3.55429169456379E-25" ixz="2.14603999851043E-15" iyy="1.81031848738356E-09" iyz="5.16987882845642E-26" izz="1.15268986006575E-09" />
    </inertial>
    <visual>
      <origin xyz="0 0 0" rpy="0 0 0" />
      <geometry>
        <mesh filename="package://jiyuan/meshes/right_wrist_link.STL" />
      </geometry>
      <material name="">
        <color rgba="0.792156862745098 0.819607843137255 0.933333333333333 1" />
      </material>
    </visual>
    <collision>
      <origin xyz="0 0 0" rpy="0 0 0" />
      <geometry>
        <mesh filename="package://jiyuan/meshes/right_wrist_link.STL" />
      </geometry>
    </collision>
  </link>
  <joint name="right_forearm_joint" type="revolute">
    <origin xyz="-0.000150000010252893 -0.241006694344342 0.112832954897592" rpy="0.448472339283537 0 -3.14159265358979" />
    <parent link="right_forearm_link" />
    <child link="right_wrist_link" />
    <axis xyz="0 0 -1" />
    <limit lower="-3.14" upper="3.14" effort="100" velocity="1" />
  </joint>
  <link name="right_wrist_cube_link">
    <inertial>
      <origin xyz="-6.92282937106714E-05 -0.00491482694116142 -7.51484021439264E-05" rpy="0 0 0" />
      <mass value="0.00188539503253632" />
      <inertia ixx="3.40886795907698E-07" ixy="4.78867177171625E-14" ixz="1.93993760245673E-10" iyy="1.59411313406911E-08" iyz="1.36656184841567E-14" izz="3.43001215981995E-07" />
    </inertial>
    <visual>
      <origin xyz="0 0 0" rpy="0 0 0" />
      <geometry>
        <mesh filename="package://jiyuan/meshes/right_wrist_cube_link.STL" />
      </geometry>
      <material name="">
        <color rgba="0.792156862745098 0.819607843137255 0.933333333333333 1" />
      </material>
    </visual>
    <collision>
      <origin xyz="0 0 0" rpy="0 0 0" />
      <geometry>
        <mesh filename="package://jiyuan/meshes/right_wrist_cube_link.STL" />
      </geometry>
    </collision>
  </link>
  <joint name="right_wrist_cube_joint" type="revolute">
    <origin xyz="0 0 0" rpy="0 0 0" />
    <parent link="right_wrist_link" />
    <child link="right_wrist_cube_link" />
    <axis xyz="1 0 0" />
    <limit lower="-3.14" upper="3.14" effort="100" velocity="1" />
  </joint>
  <link name="right_hand_link">
    <inertial>
      <origin xyz="-1.09308481710535E-09 -0.00751263403888882 7.02399793883757E-09" rpy="0 0 0" />
      <mass value="0.00350581330345173" />
      <inertia ixx="2.17576372344675E-07" ixy="2.8169092646938E-14" ixz="-2.52345647756325E-14" iyy="2.34116497931955E-07" iyz="-6.26606307607423E-15" izz="2.17576160385255E-07" />
    </inertial>
    <visual>
      <origin xyz="0 0 0" rpy="0 0 0" />
      <geometry>
        <mesh filename="package://jiyuan/meshes/right_hand_link.STL" />
      </geometry>
      <material name="">
        <color rgba="0.792156862745098 0.819607843137255 0.933333333333333 1" />
      </material>
    </visual>
    <collision>
      <origin xyz="0 0 0" rpy="0 0 0" />
      <geometry>
        <mesh filename="package://jiyuan/meshes/right_hand_link.STL" />
      </geometry>
    </collision>
  </link>
  <joint name="right_hand_cube_joint" type="revolute">
    <origin xyz="0 0 0" rpy="0 0 0" />
    <parent link="right_wrist_cube_link" />
    <child link="right_hand_link" />
    <axis xyz="0 -1 0" />
    <limit lower="-3.14" upper="3.14" effort="100" velocity="1" />
  </joint>
<link name="left_hip_pitch_engine_link">
    <inertial>
      <origin xyz="-0.00639528170474211 -5.28330276241918E-05 -1.32444315893138E-07" rpy="0 0 0" />
      <mass value="0.00680931690813817" />
      <inertia ixx="3.39928584447202E-06" ixy="-2.74780005767967E-12" ixz="1.29764844440883E-11" iyy="3.82287795367196E-06" iyz="-3.93183797563819E-11" izz="9.53831394208114E-07" />
    </inertial>
    <visual>
      <origin xyz="0 0 0" rpy="0 0 0" />
      <geometry>
        <mesh filename="package://jiyuan/meshes/left_hip_pitch_engine_link.STL" />
      </geometry>
      <material name="">
        <color rgba="1 1 1 1" />
      </material>
    </visual>
    <collision>
      <origin xyz="0 0 0" rpy="0 0 0" />
      <geometry>
        <mesh filename="package://jiyuan/meshes/left_hip_pitch_engine_link.STL" />
      </geometry>
    </collision>
  </link>
  <link name="left_hip_yaw_engine_link">
    <inertial>
      <origin xyz="-0.00997581688662634 -4.91949854028881E-05 -3.35518278792401E-06" rpy="0 0 0" />
      <mass value="0.00745115887807254" />
      <inertia ixx="4.37003711979543E-06" ixy="1.54442408912393E-20" ixz="1.55388242853849E-20" iyy="1.36593231884734E-06" iyz="-1.97036141605652E-10" izz="5.12920734013458E-06" />
    </inertial>
    <visual>
      <origin xyz="0 0 0" rpy="0 0 0" />
      <geometry>
        <mesh filename="package://jiyuan/meshes/left_hip_yaw_engine_link.STL" />
      </geometry>
      <material name="">
        <color rgba="1 1 1 1" />
      </material>
    </visual>
    <collision>
      <origin xyz="0 0 0" rpy="0 0 0" />
      <geometry>
        <mesh filename="package://jiyuan/meshes/left_hip_yaw_engine_link.STL" />
      </geometry>
    </collision>
  </link>
  <link name="left_hip_roll_link">
    <inertial>
      <origin xyz="0.0250955672145867 -0.000100584304280602 -6.72379018460021E-07" rpy="0 0 0" />
      <mass value="0.00374844887826709" />
      <inertia ixx="1.73509180930169E-07" ixy="2.26869315440614E-14" ixz="-1.348110168534E-13" iyy="5.29714495902645E-07" iyz="5.67701628384787E-10" izz="4.86108472108004E-07" />
    </inertial>
    <visual>
      <origin xyz="0 0 0" rpy="0 0 0" />
      <geometry>
        <mesh filename="package://jiyuan/meshes/left_hip_roll_link.STL" />
      </geometry>
      <material name="">
        <color rgba="0.792156862745098 0.819607843137255 0.933333333333333 1" />
      </material>
    </visual>
    <collision>
      <origin xyz="0 0 0" rpy="0 0 0" />
      <geometry>
        <mesh filename="package://jiyuan/meshes/left_hip_roll_link.STL" />
      </geometry>
    </collision>
  </link>
  <link name="left_hip_cube_link">
    <inertial>
      <origin xyz="0.00499999363631391 -4.91949854027494E-05 -2.68144890015451E-15" rpy="0 0 0" />
      <mass value="0.000245876972106249" />
      <inertia ixx="4.25015788197773E-09" ixy="6.85161708351657E-24" ixz="-4.41516842085342E-23" iyy="2.40441823778431E-09" iyz="-2.06386564924476E-15" izz="2.40441187048372E-09" />
    </inertial>
    <visual>
      <origin xyz="0 0 0" rpy="0 0 0" />
      <geometry>
        <mesh filename="package://jiyuan/meshes/left_hip_cube_link.STL" />
      </geometry>
      <material name="">
        <color rgba="0.792156862745098 0.819607843137255 0.933333333333333 1" />
      </material>
    </visual>
    <collision>
      <origin xyz="0 0 0" rpy="0 0 0" />
      <geometry>
        <mesh filename="package://jiyuan/meshes/left_hip_cube_link.STL" />
      </geometry>
    </collision>
  </link>
  <link name="left_thigh_link">
    <inertial>
      <origin xyz="-0.0338250068183917 -0.233568091984252 -0.00694723150581045" rpy="0 0 0" />
      <mass value="0.651256730970666" />
      <inertia ixx="0.00206893634437099" ixy="0.000272110721077152" ixz="-6.12788038461608E-05" iyy="0.00177958880876041" iyz="0.000133779452072601" izz="0.00201266566655095" />
    </inertial>
    <visual>
      <origin xyz="0 0 0" rpy="0 0 0" />
      <geometry>
        <mesh filename="package://jiyuan/meshes/left_thigh_link.STL" />
      </geometry>
      <material name="">
        <color rgba="0.792156862745098 0.819607843137255 0.933333333333333 1" />
      </material>
    </visual>
    <collision>
      <origin xyz="0 0 0" rpy="0 0 0" />
      <geometry>
        <mesh filename="package://jiyuan/meshes/left_thigh_link.STL" />
      </geometry>
    </collision>
  </link>
  <link name="left_shin_link">
    <inertial>
      <origin xyz="8.93525504408327E-05 -0.207812925039368 0.00356242368804441" rpy="0 0 0" />
      <mass value="0.347813967537165" />
      <inertia ixx="0.00126357262237321" ixy="-1.32038172506396E-06" ixz="-3.06631552454993E-07" iyy="0.000301407339733946" iyz="6.71088337977351E-05" izz="0.00128278527429904" />
    </inertial>
    <visual>
      <origin xyz="0 0 0" rpy="0 0 0" />
      <geometry>
        <mesh filename="package://jiyuan/meshes/left_shin_link.STL" />
      </geometry>
      <material name="">
        <color rgba="0.792156862745098 0.819607843137255 0.933333333333333 1" />
      </material>
    </visual>
    <collision>
      <origin xyz="0 0 0" rpy="0 0 0" />
      <geometry>
        <mesh filename="package://jiyuan/meshes/left_shin_link.STL" />
      </geometry>
    </collision>
  </link>
  <link name="left_ankle_cube_link">
    <inertial>
      <origin xyz="-0.025670003801888 -0.88668648907311 0.00800489820165312" rpy="0 0 0" />
      <mass value="0.000189328304341638" />
      <inertia ixx="1.15268360237197E-09" ixy="-8.75476909303627E-33" ixz="-2.1460399983049E-15" iyy="1.81031848738358E-09" iyz="-4.36007820098051E-26" izz="1.15268986006577E-09" />
    </inertial>
    <visual>
      <origin xyz="0 0 0" rpy="0 0 0" />
      <geometry>
        <mesh filename="package://jiyuan/meshes/left_ankle_cube_link.STL" />
      </geometry>
      <material name="">
        <color rgba="0.792156862745098 0.819607843137255 0.933333333333333 1" />
      </material>
    </visual>
    <collision>
      <origin xyz="0 0 0" rpy="0 0 0" />
      <geometry>
        <mesh filename="package://jiyuan/meshes/left_ankle_cube_link.STL" />
      </geometry>
    </collision>
  </link>
  <link name="left_ankle_axle_link">
    <inertial>
      <origin xyz="-6.92213906759859E-05 -0.0250851665328068 7.51570114941435E-05" rpy="0 0 0" />
      <mass value="0.00188539443116976" />
      <inertia ixx="3.40886776481147E-07" ixy="-5.50460625860004E-14" ixz="-1.93998889501305E-10" iyy="1.59411257248695E-08" iyz="-1.08549833532568E-15" izz="3.43001179235715E-07" />
    </inertial>
    <visual>
      <origin xyz="0 0 0" rpy="0 0 0" />
      <geometry>
        <mesh filename="package://jiyuan/meshes/left_ankle_axle_link.STL" />
      </geometry>
      <material name="">
        <color rgba="0.792156862745098 0.819607843137255 0.933333333333333 1" />
      </material>
    </visual>
    <collision>
      <origin xyz="0 0 0" rpy="0 0 0" />
      <geometry>
        <mesh filename="package://jiyuan/meshes/left_ankle_axle_link.STL" />
      </geometry>
    </collision>
  </link>
  <link name="left_foot_link">
    <inertial>
      <origin xyz="-0.00433742702605386 -0.0410689912642686 0.0153050659615987" rpy="0 0 0" />
      <mass value="0.138474623900111" />
      <inertia ixx="0.000249638228785326" ixy="-7.51556284441056E-08" ixz="6.92688285527476E-08" iyy="0.000245679101559375" iyz="-9.50093987655504E-06" izz="0.000115983156725437" />
    </inertial>
    <visual>
      <origin xyz="0 0 0" rpy="0 0 0" />
      <geometry>
        <mesh filename="package://jiyuan/meshes/left_foot_link.STL" />
      </geometry>
      <material name="">
        <color rgba="0.792156862745098 0.819607843137255 0.933333333333333 1" />
      </material>
    </visual>
    <collision>
      <origin xyz="0 0 0" rpy="0 0 0" />
      <geometry>
        <mesh filename="package://jiyuan/meshes/left_foot_link.STL" />
      </geometry>
    </collision>
  </link>
  <link name="left_toe_link">
    <inertial>
      <origin xyz="-0.000572444640377659 0.00216340409996052 0.021116546041816" rpy="0 0 0" />
      <mass value="0.0528822247684903" />
      <inertia ixx="3.25175653226149E-05" ixy="-1.62060260555305E-08" ixz="-8.56599509772465E-07" iyy="5.35566607091479E-05" iyz="-5.09324728976432E-08" izz="3.36873480136063E-05" />
    </inertial>
    <visual>
      <origin xyz="0 0 0" rpy="0 0 0" />
      <geometry>
        <mesh filename="package://jiyuan/meshes/left_toe_link.STL" />
      </geometry>
      <material name="">
        <color rgba="0.792156862745098 0.819607843137255 0.933333333333333 1" />
      </material>
    </visual>
    <collision>
      <origin xyz="0 0 0" rpy="0 0 0" />
      <geometry>
        <mesh filename="package://jiyuan/meshes/left_toe_link.STL" />
      </geometry>
    </collision>
  </link>
  <link name="left_branch_link">
    <inertial>
      <origin xyz="0.0342087441276741 -0.00176734097123937 -0.00120947727238396" rpy="0 0 0" />
      <mass value="0.013497890740739" />
      <inertia ixx="1.2926414536493E-06" ixy="5.38399776707783E-08" ixz="4.32856935211769E-08" iyy="1.06891317628328E-06" iyz="3.95744816457389E-09" izz="1.75257133082468E-06" />
    </inertial>
    <visual>
      <origin xyz="0 0 0" rpy="0 0 0" />
      <geometry>
        <mesh filename="package://jiyuan/meshes/left_branch_link.STL" />
      </geometry>
      <material name="">
        <color rgba="0.792156862745098 0.819607843137255 0.933333333333333 1" />
      </material>
    </visual>
    <collision>
      <origin xyz="0 0 0" rpy="0 0 0" />
      <geometry>
        <mesh filename="package://jiyuan/meshes/left_branch_link.STL" />
      </geometry>
    </collision>
  </link>
  <link name="left_spine_003_link">
    <inertial>
      <origin xyz="0.00036404463207966 0.0420089912020032 -0.0225452756157186" rpy="0 0 0" />
      <mass value="0.0192570395361066" />
      <inertia ixx="3.29487915932372E-06" ixy="-5.96656270484953E-08" ixz="2.76839158630015E-07" iyy="2.37144676466391E-06" iyz="3.13580776458497E-07" izz="2.15117263561911E-06" />
    </inertial>
    <visual>
      <origin xyz="0 0 0" rpy="0 0 0" />
      <geometry>
        <mesh filename="package://jiyuan/meshes/left_spine_003_link.STL" />
      </geometry>
      <material name="">
        <color rgba="0.792156862745098 0.819607843137255 0.933333333333333 0.25" />
      </material>
    </visual>
    <collision>
      <origin xyz="0 0 0" rpy="0 0 0" />
      <geometry>
        <mesh filename="package://jiyuan/meshes/left_spine_003_link.STL" />
      </geometry>
    </collision>
  </link>
  <link name="left_spine_004_ground_link">
    <inertial>
      <origin xyz="0.0334438419965927 0.0335246343121994 0.025836416760253" rpy="0 0 0" />
      <mass value="0.0371077097805639" />
      <inertia ixx="1.15914902522178E-05" ixy="-1.87344982433402E-08" ixz="-4.94055284300337E-07" iyy="1.17589174084433E-05" iyz="-1.04248798188576E-08" izz="1.87631928022744E-05" />
    </inertial>
    <visual>
      <origin xyz="0 0 0" rpy="0 0 0" />
      <geometry>
        <mesh filename="package://jiyuan/meshes/left_spine_004_ground_link.STL" />
      </geometry>
      <material name="">
        <color rgba="0.792156862745098 0.819607843137255 0.933333333333333 1" />
      </material>
    </visual>
    <collision>
      <origin xyz="0 0 0" rpy="0 0 0" />
      <geometry>
        <mesh filename="package://jiyuan/meshes/left_spine_004_ground_link.STL" />
      </geometry>
    </collision>
  </link>
  <link name="left_spine_004_link">
    <inertial>
      <origin xyz="0.028182942237352 8.13448473200862E-05 2.7605138357284E-06" rpy="0 0 0" />
      <mass value="0.00196590214384828" />
      <inertia ixx="2.04393171947593E-08" ixy="1.45941256926745E-10" ixz="2.98882648257208E-10" iyy="3.48329498920359E-07" iyz="6.34072572822225E-10" izz="3.5162747886882E-07" />
    </inertial>
    <visual>
      <origin xyz="0 0 0" rpy="0 0 0" />
      <geometry>
        <mesh filename="package://jiyuan/meshes/left_spine_004_link.STL" />
      </geometry>
      <material name="">
        <color rgba="0.792156862745098 0.819607843137255 0.933333333333333 1" />
      </material>
    </visual>
    <collision>
      <origin xyz="0 0 0" rpy="0 0 0" />
      <geometry>
        <mesh filename="package://jiyuan/meshes/left_spine_004_link.STL" />
      </geometry>
    </collision>
  </link>
  <link name="left_shoulder_link">
    <inertial>
      <origin xyz="4.60695540049905E-09 -1.3096792217393E-07 1.04989524490895E-07" rpy="0 0 0" />
      <mass value="5.46299456939302E-05" />
      <inertia ixx="3.36280041911811E-10" ixy="-5.21892557811385E-16" ixz="-3.92534891888924E-14" iyy="2.67929781003683E-10" iyz="1.55043618776817E-15" izz="2.67928900864954E-10" />
    </inertial>
    <visual>
      <origin xyz="0 0 0" rpy="0 0 0" />
      <geometry>
        <mesh filename="package://jiyuan/meshes/left_shoulder_link.STL" />
      </geometry>
      <material name="">
        <color rgba="0.792156862745098 0.819607843137255 0.933333333333333 1" />
      </material>
    </visual>
    <collision>
      <origin xyz="0 0 0" rpy="0 0 0" />
      <geometry>
        <mesh filename="package://jiyuan/meshes/left_shoulder_link.STL" />
      </geometry>
    </collision>
  </link>
  <link name="left_arm_link">
    <inertial>
      <origin xyz="-0.0452987392277859 -0.0797744953070252 0.0108548928586347" rpy="0 0 0" />
      <mass value="0.0463841814445341" />
      <inertia ixx="2.78725979874452E-05" ixy="-4.19823686112728E-07" ixz="9.55350276886978E-08" iyy="6.10545701242481E-06" iyz="3.31966464599818E-06" izz="2.78003362567239E-05" />
    </inertial>
    <visual>
      <origin xyz="0 0 0" rpy="0 0 0" />
      <geometry>
        <mesh filename="package://jiyuan/meshes/left_arm_link.STL" />
      </geometry>
      <material name="">
        <color rgba="0.792156862745098 0.819607843137255 0.933333333333333 1" />
      </material>
    </visual>
    <collision>
      <origin xyz="0 0 0" rpy="0 0 0" />
      <geometry>
        <mesh filename="package://jiyuan/meshes/left_arm_link.STL" />
      </geometry>
    </collision>
  </link>
  <link name="left_forearm_link">
    <inertial>
      <origin xyz="-0.000155041944261053 -0.140426426569951 0.0644320441565459" rpy="0 0 0" />
      <mass value="0.0295290267369982" />
      <inertia ixx="1.2939795738133E-05" ixy="-2.15707921034777E-10" ixz="8.17675472287479E-11" iyy="4.84789752124762E-06" iyz="3.71681839138466E-06" izz="1.1064910717755E-05" />
    </inertial>
    <visual>
      <origin xyz="0 0 0" rpy="0 0 0" />
      <geometry>
        <mesh filename="package://jiyuan/meshes/left_forearm_link.STL" />
      </geometry>
      <material name="">
        <color rgba="1 1 1 1" />
      </material>
    </visual>
    <collision>
      <origin xyz="0 0 0" rpy="0 0 0" />
      <geometry>
        <mesh filename="package://jiyuan/meshes/left_forearm_link.STL" />
      </geometry>
    </collision>
  </link>
  <link name="left_wrist_link">
    <inertial>
      <origin xyz="-2.77555756156289E-17 -0.0299999966730439 -5.55111512312578E-17" rpy="0 0 0" />
      <mass value="0.000189328304341632" />
      <inertia ixx="1.15268360237195E-09" ixy="3.55429169456379E-25" ixz="2.14603999851043E-15" iyy="1.81031848738356E-09" iyz="5.16987882845642E-26" izz="1.15268986006575E-09" />
    </inertial>
    <visual>
      <origin xyz="0 0 0" rpy="0 0 0" />
      <geometry>
        <mesh filename="package://jiyuan/meshes/left_wrist_link.STL" />
      </geometry>
      <material name="">
        <color rgba="0.792156862745098 0.819607843137255 0.933333333333333 1" />
      </material>
    </visual>
    <collision>
      <origin xyz="0 0 0" rpy="0 0 0" />
      <geometry>
        <mesh filename="package://jiyuan/meshes/left_wrist_link.STL" />
      </geometry>
    </collision>
  </link>
  <link name="left_wrist_cube_link">
    <inertial>
      <origin xyz="-6.92282937106714E-05 -0.00491482694116142 -7.51484021439264E-05" rpy="0 0 0" />
      <mass value="0.00188539503253632" />
      <inertia ixx="3.40886795907698E-07" ixy="4.78867177171625E-14" ixz="1.93993760245673E-10" iyy="1.59411313406911E-08" iyz="1.36656184841567E-14" izz="3.43001215981995E-07" />
    </inertial>
    <visual>
      <origin xyz="0 0 0" rpy="0 0 0" />
      <geometry>
        <mesh filename="package://jiyuan/meshes/left_wrist_cube_link.STL" />
      </geometry>
      <material name="">
        <color rgba="0.792156862745098 0.819607843137255 0.933333333333333 1" />
      </material>
    </visual>
    <collision>
      <origin xyz="0 0 0" rpy="0 0 0" />
      <geometry>
        <mesh filename="package://jiyuan/meshes/left_wrist_cube_link.STL" />
      </geometry>
    </collision>
  </link>
  <link name="left_hand_link">
    <inertial>
      <origin xyz="-1.09308481710535E-09 -0.00751263403888882 7.02399793883757E-09" rpy="0 0 0" />
      <mass value="0.00350581330345173" />
      <inertia ixx="2.17576372344675E-07" ixy="2.8169092646938E-14" ixz="-2.52345647756325E-14" iyy="2.34116497931955E-07" iyz="-6.26606307607423E-15" izz="2.17576160385255E-07" />
    </inertial>
    <visual>
      <origin xyz="0 0 0" rpy="0 0 0" />
      <geometry>
        <mesh filename="package://jiyuan/meshes/left_hand_link.STL" />
      </geometry>
      <material name="">
        <color rgba="0.792156862745098 0.819607843137255 0.933333333333333 1" />
      </material>
    </visual>
    <collision>
      <origin xyz="0 0 0" rpy="0 0 0" />
      <geometry>
        <mesh filename="package://jiyuan/meshes/left_hand_link.STL" />
      </geometry>
    </collision>
  </link>
  <joint name="left_hip_pitch_engine_joint" type="revolute">
    <origin xyz="0.0843332 2.45945e-05 0" rpy="0 0 -0" />
    <parent link="base_link" />
    <child link="left_hip_pitch_engine_link" />
    <axis xyz="-0 0 1" />
    <limit lower="-3.14" upper="3.14" effort="100" velocity="1" />
  </joint>
  <joint name="left_hip_yaw_engine_joint" type="revolute">
    <origin xyz="0.0843332 2.45945e-05 0" rpy="0 0 -0" />
    <parent link="base_link" />
    <child link="left_hip_yaw_engine_link" />
    <axis xyz="-0 1 0" />
    <limit lower="-3.14" upper="3.14" effort="100" velocity="1" />
  </joint>
  <joint name="left_hip_roll_joint" type="revolute">
    <origin xyz="0.0843332 2.45945e-05 0" rpy="0 0 -0" />
    <parent link="base_link" />
    <child link="left_hip_roll_link" />
    <axis xyz="1 0 0" />
    <limit lower="-3.14" upper="3.14" effort="100" velocity="1" />
  </joint>
  <joint name="left_hip_cube_joint" type="revolute">
    <origin xyz="-0 0 0" rpy="0 0 -0" />
    <parent link="left_hip_roll_link" />
    <child link="left_hip_cube_link" />
    <axis xyz="-0 0 1" />
    <limit lower="-3.14" upper="3.14" effort="100" velocity="1" />
  </joint>
  <joint name="left_thigh_joint" type="revolute">
    <origin xyz="-0 0 0" rpy="0 0 -0" />
    <parent link="left_hip_cube_link" />
    <child link="left_thigh_link" />
    <axis xyz="-0 1 0" />
    <limit lower="-3.14" upper="3.14" effort="100" velocity="1" />
  </joint>
  <joint name="left_knee_joint" type="revolute">
    <origin xyz="0.0256668 -0.429825 -0.0115" rpy="0 0 -0" />
    <parent link="left_thigh_link" />
    <child link="left_shin_link" />
    <axis xyz="-1 0 0" />
    <limit lower="-3.14" upper="3.14" effort="100" velocity="1" />
  </joint>
  <joint name="left_ankle_cube_joint" type="revolute">
    <origin xyz="-0.0256668 0.429825 0.0115" rpy="0 0 -0" />
    <parent link="left_shin_link" />
    <child link="left_ankle_cube_link" />
    <axis xyz="-0 0 1" />
    <limit lower="-3.14" upper="3.14" effort="100" velocity="1" />
  </joint>
  <joint name="left_ankle_axle_joint" type="revolute">
    <origin xyz="0.02567 -0.886686 0.00800489" rpy="0 0 -0" />
    <parent link="left_ankle_cube_link" />
    <child link="left_ankle_axle_link" />
    <axis xyz="-1 0 0" />
    <limit lower="-3.14" upper="3.14" effort="100" velocity="1" />
  </joint>
  <joint name="left_foot_joint" type="revolute">
    <origin xyz="-0 -0.01475 0" rpy="0 0 -0" />
    <parent link="left_ankle_axle_link" />
    <child link="left_foot_link" />
    <axis xyz="-0 -1 0" />
    <limit lower="-3.14" upper="3.14" effort="100" velocity="1" />
  </joint>
  <joint name="left_toe_joint" type="revolute">
    <origin xyz="-0.0005 -0.0646056 0.105615" rpy="0 0 -0" />
    <parent link="left_foot_link" />
    <child link="left_toe_link" />
    <axis xyz="-1 0 0" />
    <limit lower="-3.14" upper="3.14" effort="100" velocity="1" />
  </joint>
  <joint name="left_branch_link" type="fixed">
    <origin xyz="0.0772641 0.10221 0.00749937" rpy="3.16096e-05 0.114737 0.00748937" />
    <parent link="spine_002_link" />
    <child link="left_branch_link" />
    <axis xyz="-0 0 0" />
    <limit lower="-3.14" upper="3.14" effort="100" velocity="1" />
  </joint>
  <joint name="left_spine_002_joint" type="revolute">
    <origin xyz="-0 0 0" rpy="0 0 -0" />
    <parent link="left_branch_link" />
    <child link="left_spine_003_link" />
    <axis xyz="-0.000274286 -1 0" />
    <limit lower="-3.14" upper="3.14" effort="100" velocity="1" />
  </joint>
  <joint name="left_spine_003_joint" type="revolute">
    <origin xyz="0.00410736 0.0729963 -0.0467839" rpy="3.11428e-19 1.48365 -0.000274286" />
    <parent link="left_spine_003_link" />
    <child link="left_spine_004_ground_link" />
    <axis xyz="1 0 0" />
    <limit lower="-3.14" upper="3.14" effort="100" velocity="1" />
  </joint>
  <joint name="left_spine_004_ground_joint" type="revolute">
    <origin xyz="-0.0432454 0.0420609 0.0515776" rpy="-0.398519 -1.57035 0.660318" />
    <parent link="left_spine_004_ground_link" />
    <child link="left_spine_004_link" />
    <axis xyz="-0.999999 -0.000443611 -0.000901501" />
    <limit lower="-3.14" upper="3.14" effort="100" velocity="1" />
  </joint>
  <joint name="left_spine_004_joint" type="revolute">
    <origin xyz="-0 0 0" rpy="0 0 -0" />
    <parent link="left_spine_004_link" />
    <child link="left_shoulder_link" />
    <axis xyz="-0.000859407 -0.0871558 0.996194" />
    <limit lower="-3.14" upper="3.14" effort="100" velocity="1" />
  </joint>
  <joint name="left_shoulder_joint" type="revolute">
    <origin xyz="-0 0 0" rpy="0 0 -0" />
    <parent link="left_shoulder_link" />
    <child link="left_arm_link" />
    <axis xyz="-0.000859407 -0.0871558 0.996194" />
    <limit lower="-3.14" upper="3.14" effort="100" velocity="1" />
  </joint>
  <joint name="left_elbow_joint" type="revolute">
    <origin xyz="0.0456519 -0.198226 0.0273941" rpy="-0.131652 -0.173467 0.024955" />
    <parent link="left_arm_link" />
    <child link="left_forearm_link" />
    <axis xyz="1 0 0" />
    <limit lower="-3.14" upper="3.14" effort="100" velocity="1" />
  </joint>
  <joint name="left_forearm_joint" type="revolute">
    <origin xyz="0.00015 -0.241007 0.112833" rpy="0.448472 0 3.14159" />
    <parent link="left_forearm_link" />
    <child link="left_wrist_link" />
    <axis xyz="-0 0 -1" />
    <limit lower="-3.14" upper="3.14" effort="100" velocity="1" />
  </joint>
  <joint name="left_wrist_cube_joint" type="revolute">
    <origin xyz="-0 0 0" rpy="0 0 -0" />
    <parent link="left_wrist_link" />
    <child link="left_wrist_cube_link" />
    <axis xyz="-1 0 0" />
    <limit lower="-3.14" upper="3.14" effort="100" velocity="1" />
  </joint>
  <joint name="left_hand_cube_joint" type="revolute">
    <origin xyz="-0 0 0" rpy="0 0 -0" />
    <parent link="left_wrist_cube_link" />
    <child link="left_hand_link" />
    <axis xyz="-0 -1 0" />
    <limit lower="-3.14" upper="3.14" effort="100" velocity="1" />
  </joint>
</robot>