<?xml version="1.0" encoding="utf-8" ?>
<!-- This URDF was automatically created by SolidWorks to URDF Exporter! Originally created by Stephen Brawner (brawner@gmail.com)
     Commit Version: 1.6.0-1-g15f4949  Build Version: 1.6.7594.29634
     For more information, please see http://wiki.ros.org/sw_urdf_exporter -->
<robot name="assets">
  <link name="base_link">
    <inertial>
      <origin
                xyz="0.000354696592758407 0.0509167128985148 -0.00216482908207528"
                rpy="0 0 0"
            />
      <mass value="0.557304827590303" />
      <inertia
                ixx="0.00246193712584463"
                ixy="-1.82360813179016E-06"
                ixz="-1.56220534472292E-06"
                iyy="0.00268884325216682"
                iyz="0.000482267737660755"
                izz="0.00265779316409685"
            />
    </inertial>
    <visual>
      <origin xyz="0 0 0" rpy="0 0 0" />
      <geometry>
        <mesh filename="package://assets/meshes/base_link.STL" />
      </geometry>
      <material name="">
        <color rgba="1 1 1 1" />
      </material>
    </visual>
    <collision>
      <origin xyz="0 0 0" rpy="0 0 0" />
      <geometry>
        <mesh filename="package://assets/meshes/base_link.STL" />
      </geometry>
    </collision>
  </link>
  <link name="right_hip_pitch_engine_link">
    <inertial>
      <origin
                xyz="-0.0132180319673854 -0.000409478998264526 -0.000337079988808422"
                rpy="0 0 0"
            />
      <mass value="0.00784384827917925" />
      <inertia
                ixx="4.36590682410741E-06"
                ixy="-2.17338446163864E-08"
                ixz="3.13928980680945E-12"
                iyy="5.12008779916659E-06"
                iyz="2.54645518130558E-10"
                izz="1.36310392622543E-06"
            />
    </inertial>
    <visual>
      <origin xyz="0 0 0" rpy="0 0 0" />
      <geometry>
        <mesh
                    filename="package://assets/meshes/right_hip_pitch_engine_link.STL"
                />
      </geometry>
      <material name="">
        <color rgba="1 1 1 1" />
      </material>
    </visual>
    <collision>
      <origin xyz="0 0 0" rpy="0 0 0" />
      <geometry>
        <mesh
                    filename="package://assets/meshes/right_hip_pitch_engine_link.STL"
                />
      </geometry>
    </collision>
  </link>
  <joint name="right_hip_pitch_engine_joint" type="revolute">
    <origin xyz="-0.084333 2.46E-05 0" rpy="0 0 0" />
    <parent link="base_link" />
    <child link="right_hip_pitch_engine_link" />
    <axis xyz="0 0 1" />
    <limit lower="-3.14" upper="3.14" effort="2.5" velocity="1" />
  </joint>
  <link name="right_hip_yaw_engine_link">
    <inertial>
      <origin
                xyz="-0.00975037082028439 0.000335610218016511 0.000145803243278274"
                rpy="0 0 0"
            />
      <mass value="0.00721229273746498" />
      <inertia
                ixx="3.40368793351683E-06"
                ixy="-1.02845782049211E-10"
                ixz="6.11483129271824E-09"
                iyy="9.55584405344269E-07"
                iyz="-9.57299401352983E-11"
                izz="3.82715081231712E-06"
            />
    </inertial>
    <visual>
      <origin xyz="0 0 0" rpy="0 0 0" />
      <geometry>
        <mesh
                    filename="package://assets/meshes/right_hip_yaw_engine_link.STL"
                />
      </geometry>
      <material name="">
        <color rgba="1 1 1 1" />
      </material>
    </visual>
    <collision>
      <origin xyz="0 0 0" rpy="0 0 0" />
      <geometry>
        <mesh
                    filename="package://assets/meshes/right_hip_yaw_engine_link.STL"
                />
      </geometry>
    </collision>
  </link>
  <joint name="right_hip_yaw_engine_joint" type="revolute">
    <origin xyz="-0.084333 2.46E-05 0" rpy="0 0 0" />
    <parent link="base_link" />
    <child link="right_hip_yaw_engine_link" />
    <axis xyz="0 1 0" />
    <limit lower="-3.14" upper="3.14" effort="8" velocity="1" />
  </joint>
  <link name="right_hip_roll_link">
    <inertial>
      <origin
                xyz="0.0222625122554699 -4.28350421400515E-05 -2.24420624569832E-05"
                rpy="0 0 0"
            />
      <mass value="0.00398432706561057" />
      <inertia
                ixx="1.88235287338231E-07"
                ixy="2.1552063298453E-14"
                ixz="-1.42365151023063E-13"
                iyy="5.49391206748978E-07"
                iyz="1.59954822662213E-10"
                izz="5.05938324031621E-07"
            />
    </inertial>
    <visual>
      <origin xyz="0 0 0" rpy="0 0 0" />
      <geometry>
        <mesh filename="package://assets/meshes/right_hip_roll_link.STL" />
      </geometry>
      <material name="">
        <color rgba="0.792156862745098 0.819607843137255 0.933333333333333 1" />
      </material>
    </visual>
    <collision>
      <origin xyz="0 0 0" rpy="0 0 0" />
      <geometry>
        <mesh filename="package://assets/meshes/right_hip_roll_link.STL" />
      </geometry>
    </collision>
  </link>
  <joint name="right_hip_roll_joint" type="revolute">
    <origin xyz="-0.084333 2.46E-05 0" rpy="0 0 0" />
    <parent link="base_link" />
    <child link="right_hip_roll_link" />
    <axis xyz="1 0 0" />
    <limit lower="-3.14" upper="3.14" effort="8" velocity="1" />
  </joint>
  <link name="right_hip_cube_link">
    <inertial>
      <origin
                xyz="-7.58236988473993E-09 -8.10037224742346E-14 8.6035271838651E-15"
                rpy="0 0 0"
            />
      <mass value="0.000245876972106248" />
      <inertia
                ixx="4.25015788197772E-09"
                ixy="3.10894475768081E-24"
                ixz="-5.60964659632742E-25"
                iyy="2.40441818298092E-09"
                iyz="2.14603999890957E-15"
                izz="2.40441192528711E-09"
            />
    </inertial>
    <visual>
      <origin xyz="0 0 0" rpy="0 0 0" />
      <geometry>
        <mesh filename="package://assets/meshes/right_hip_cube_link.STL" />
      </geometry>
      <material name="">
        <color rgba="0.792156862745098 0.819607843137255 0.933333333333333 1" />
      </material>
    </visual>
    <collision>
      <origin xyz="0 0 0" rpy="0 0 0" />
      <geometry>
        <mesh filename="package://assets/meshes/right_hip_cube_link.STL" />
      </geometry>
    </collision>
  </link>
  <joint name="right_hip_cube_joint" type="revolute">
    <origin xyz="0 0 0" rpy="0 0 0" />
    <parent link="right_hip_roll_link" />
    <child link="right_hip_cube_link" />
    <axis xyz="0 0 1" />
    <limit lower="-3.14" upper="3.14" effort="8" velocity="1" />
  </joint>
  <link name="right_thigh_link">
    <inertial>
      <origin
                xyz="-0.0353507257648988 -0.247894844440165 0.00178440950269929"
                rpy="0 0 0"
            />
      <mass value="0.807844023825405" />
      <inertia
                ixx="0.00262872199337436"
                ixy="0.000322284655114814"
                ixz="-6.13684271429916E-05"
                iyy="0.00181775503594599"
                iyz="0.000137456961428372"
                izz="0.00258154933740886"
            />
    </inertial>
    <visual>
      <origin xyz="0 0 0" rpy="0 0 0" />
      <geometry>
        <mesh filename="package://assets/meshes/right_thigh_link.STL" />
      </geometry>
      <material name="">
        <color rgba="0.792156862745098 0.819607843137255 0.933333333333333 1" />
      </material>
    </visual>
    <collision>
      <origin xyz="0 0 0" rpy="0 0 0" />
      <geometry>
        <mesh filename="package://assets/meshes/right_thigh_link.STL" />
      </geometry>
    </collision>
  </link>
  <joint name="right_thigh_joint" type="revolute">
    <origin xyz="0 0 0" rpy="0 0 0" />
    <parent link="right_hip_cube_link" />
    <child link="right_thigh_link" />
    <axis xyz="0 1 0" />
    <limit lower="-3.14" upper="3.14" effort="8" velocity="1" />
  </joint>
  <link name="right_shin_link">
    <inertial>
      <origin
                xyz="0.00524376700949104 -0.205627168869245 0.00732812606870403"
                rpy="0 0 0"
            />
      <mass value="0.364323955321575" />
      <inertia
                ixx="0.00132460554133456"
                ixy="-1.48476057216079E-06"
                ixz="-3.28201858976119E-07"
                iyy="0.000315850437296788"
                iyz="7.27055941848168E-05"
                izz="0.00134334443677415"
            />
    </inertial>
    <visual>
      <origin xyz="0 0 0" rpy="0 0 0" />
      <geometry>
        <mesh filename="package://assets/meshes/right_shin_link.STL" />
      </geometry>
      <material name="">
        <color rgba="1 1 1 1" />
      </material>
    </visual>
    <collision>
      <origin xyz="0 0 0" rpy="0 0 0" />
      <geometry>
        <mesh filename="package://assets/meshes/right_shin_link.STL" />
      </geometry>
    </collision>
  </link>
  <joint name="right_knee_joint" type="revolute">
    <origin
            xyz="-0.0324938548812839 -0.429595785329822 -0.011499999999998"
            rpy="0 0 0"
        />
    <parent link="right_thigh_link" />
    <child link="right_shin_link" />
    <axis xyz="-1 0 0" />
    <limit lower="-3.14" upper="3.14" effort="8" velocity="1" />
  </joint>
  <link name="right_ankle_1_3_link">
    <inertial>
      <origin
                xyz="-6.03425108214317E-08 -0.00133748853041993 0.000181477957767302"
                rpy="0 0 0"
            />
      <mass value="0.00262097004680966" />
      <inertia
                ixx="8.99652249736952E-08"
                ixy="2.36331351065569E-17"
                ixz="-2.11782435234631E-16"
                iyy="9.24849140747278E-08"
                iyz="-1.78782548164191E-10"
                izz="1.40840739837435E-07"
            />
    </inertial>
    <visual>
      <origin xyz="0 0 0" rpy="0 0 0" />
      <geometry>
        <mesh filename="package://assets/meshes/right_ankle_1_3_link.STL" />
      </geometry>
      <material name="">
        <color rgba="0.792156862745098 0.819607843137255 0.933333333333333 1" />
      </material>
    </visual>
    <collision>
      <origin xyz="0 0 0" rpy="0 0 0" />
      <geometry>
        <mesh filename="package://assets/meshes/right_ankle_1_3_link.STL" />
      </geometry>
    </collision>
  </link>
  <joint name="right_ankle_1_3_joint" type="revolute">
    <origin
            xyz="0.00499998365963887 -0.435500013525673 0.00299999395255281"
            rpy="0 0 0"
        />
    <parent link="right_shin_link" />
    <child link="right_ankle_1_3_link" />
    <axis xyz="0 0 1" />
    <limit lower="-3.14" upper="3.14" effort="2.5" velocity="1" />
  </joint>
  <link name="right_ankle_1_3_cube_link">
    <inertial>
      <origin
                xyz="1.63396522423476E-08 -0.0170076971502238 1.27962296526257E-07"
                rpy="0 0 0"
            />
      <mass value="0.00141938195347877" />
      <inertia
                ixx="2.85047557512365E-08"
                ixy="1.23379661362193E-15"
                ixz="1.97863769928964E-13"
                iyy="3.24387028605849E-08"
                iyz="6.23241857794277E-14"
                izz="3.91865632006432E-08"
            />
    </inertial>
    <visual>
      <origin xyz="0 0 0" rpy="0 0 0" />
      <geometry>
        <mesh
                    filename="package://assets/meshes/right_ankle_1_3_cube_link.STL"
                />
      </geometry>
      <material name="">
        <color rgba="0.792156862745098 0.819607843137255 0.933333333333333 1" />
      </material>
    </visual>
    <collision>
      <origin xyz="0 0 0" rpy="0 0 0" />
      <geometry>
        <mesh
                    filename="package://assets/meshes/right_ankle_1_3_cube_link.STL"
                />
      </geometry>
    </collision>
  </link>
  <joint name="right_ankle_1_3_cube_joint" type="revolute">
    <origin xyz="0 0 0" rpy="0 0 0" />
    <parent link="right_ankle_1_3_link" />
    <child link="right_ankle_1_3_cube_link" />
    <axis xyz="0 -1 0" />
    <limit lower="-3.14" upper="3.14" effort="2.5" velocity="1" />
  </joint>
  <link name="right_ankle_1_3_page_link">
    <inertial>
      <origin
                xyz="-0.000120807831869477 -0.0207078096816944 4.90926743701436E-16"
                rpy="0 0 0"
            />
      <mass value="0.00310095806973402" />
      <inertia
                ixx="6.607387135913E-07"
                ixy="-1.12233481706802E-09"
                ixz="1.70217018730304E-13"
                iyy="1.0799072162633E-07"
                iyz="-2.85559813915869E-21"
                izz="6.98721337032829E-07"
            />
    </inertial>
    <visual>
      <origin xyz="0 0 0" rpy="0 0 0" />
      <geometry>
        <mesh
                    filename="package://assets/meshes/right_ankle_1_3_page_link.STL"
                />
      </geometry>
      <material name="">
        <color rgba="0.792156862745098 0.819607843137255 0.933333333333333 1" />
      </material>
    </visual>
    <collision>
      <origin xyz="0 0 0" rpy="0 0 0" />
      <geometry>
        <mesh
                    filename="package://assets/meshes/right_ankle_1_3_page_link.STL"
                />
      </geometry>
    </collision>
  </link>
  <joint name="right_ankle_1_3_page_joint" type="revolute">
    <origin xyz="0 -0.0199999864743267 0" rpy="0 0 0" />
    <parent link="right_ankle_1_3_cube_link" />
    <child link="right_ankle_1_3_page_link" />
    <axis xyz="-1 0 0" />
    <limit lower="-3.14" upper="3.14" effort="2.5" velocity="1" />
  </joint>
  <link name="right_ankle_2_3_link">
    <inertial>
      <origin
                xyz="-9.00902660042058E-08 -0.00133748853041982 0.000181483037757071"
                rpy="0 0 0"
            />
      <mass value="0.00262097004680966" />
      <inertia
                ixx="8.99652249736953E-08"
                ixy="2.36331814507264E-17"
                ixz="-2.11782433500853E-16"
                iyy="9.24849140747277E-08"
                iyz="-1.78782548163735E-10"
                izz="1.40840739837435E-07"
            />
    </inertial>
    <visual>
      <origin xyz="0 0 0" rpy="0 0 0" />
      <geometry>
        <mesh filename="package://assets/meshes/right_ankle_2_3_link.STL" />
      </geometry>
      <material name="">
        <color rgba="0.831372549019608 0.670588235294118 0.129411764705882 1" />
      </material>
    </visual>
    <collision>
      <origin xyz="0 0 0" rpy="0 0 0" />
      <geometry>
        <mesh filename="package://assets/meshes/right_ankle_2_3_link.STL" />
      </geometry>
    </collision>
  </link>
  <joint name="right_ankle_2_3_joint" type="revolute">
    <origin
            xyz="-0.0136195625217264 -0.435500013525674 0.0352499939525529"
            rpy="3.14159265358979 1.04719755119659 3.14159265358979"
        />
    <parent link="right_shin_link" />
    <child link="right_ankle_2_3_link" />
    <axis xyz="0 0 1" />
    <limit lower="-3.14" upper="3.14" effort="2.5" velocity="1" />
  </joint>
  <link name="right_ankle_2_3_cube_link">
    <inertial>
      <origin
                xyz="-1.3408035869078E-08 -0.0170076970709049 1.33042210040402E-07"
                rpy="0 0 0"
            />
      <mass value="0.00141938194566218" />
      <inertia
                ixx="2.85047550653728E-08"
                ixy="1.23560668078161E-15"
                ixz="1.9786893847569E-13"
                iyy="3.24387030714843E-08"
                iyz="6.23251110451125E-14"
                izz="3.91865625370975E-08"
            />
    </inertial>
    <visual>
      <origin xyz="0 0 0" rpy="0 0 0" />
      <geometry>
        <mesh
                    filename="package://assets/meshes/right_ankle_2_3_cube_link.STL"
                />
      </geometry>
      <material name="">
        <color rgba="0.792156862745098 0.819607843137255 0.933333333333333 1" />
      </material>
    </visual>
    <collision>
      <origin xyz="0 0 0" rpy="0 0 0" />
      <geometry>
        <mesh
                    filename="package://assets/meshes/right_ankle_2_3_cube_link.STL"
                />
      </geometry>
    </collision>
  </link>
  <joint name="right_ankle_2_3_cube_joint" type="revolute">
    <origin xyz="0 0 0" rpy="0 0 0" />
    <parent link="right_ankle_2_3_link" />
    <child link="right_ankle_2_3_cube_link" />
    <axis xyz="0 -1 0" />
    <limit lower="-3.14" upper="3.14" effort="2.5" velocity="1" />
  </joint>
  <link name="right_ankle_2_3_page_link">
    <inertial>
      <origin
                xyz="-0.000120807831848452 -0.0207078096816944 -1.45994327738208E-14"
                rpy="0 0 0"
            />
      <mass value="0.00310095806973403" />
      <inertia
                ixx="6.60738713591303E-07"
                ixy="-1.12233481706538E-09"
                ixz="1.70217019139848E-13"
                iyy="1.0799072162633E-07"
                iyz="3.84018584416454E-21"
                izz="6.98721337032832E-07"
            />
    </inertial>
    <visual>
      <origin xyz="0 0 0" rpy="0 0 0" />
      <geometry>
        <mesh
                    filename="package://assets/meshes/right_ankle_2_3_page_link.STL"
                />
      </geometry>
      <material name="">
        <color rgba="0.792156862745098 0.819607843137255 0.933333333333333 1" />
      </material>
    </visual>
    <collision>
      <origin xyz="0 0 0" rpy="0 0 0" />
      <geometry>
        <mesh
                    filename="package://assets/meshes/right_ankle_2_3_page_link.STL"
                />
      </geometry>
    </collision>
  </link>
  <joint name="right_ankle_2_3_page_joint" type="revolute">
    <origin xyz="0 -0.0199999864743262 0" rpy="0 0 0" />
    <parent link="right_ankle_2_3_cube_link" />
    <child link="right_ankle_2_3_page_link" />
    <axis xyz="1 0 0" />
    <limit lower="-3.14" upper="3.14" effort="2.5" velocity="1" />
  </joint>
  <link name="right_ankle_3_3_link">
    <inertial>
      <origin
                xyz="-7.96157886978621E-08 -0.00133748853042004 0.000181454735450504"
                rpy="0 0 0"
            />
      <mass value="0.00262097004680966" />
      <inertia
                ixx="8.99652249736953E-08"
                ixy="2.36329726341311E-17"
                ixz="-2.11782393796184E-16"
                iyy="9.24849140747277E-08"
                iyz="-1.78782548163856E-10"
                izz="1.40840739837435E-07"
            />
    </inertial>
    <visual>
      <origin xyz="0 0 0" rpy="0 0 0" />
      <geometry>
        <mesh filename="package://assets/meshes/right_ankle_3_3_link.STL" />
      </geometry>
      <material name="">
        <color rgba="0.792156862745098 0.819607843137255 0.933333333333333 1" />
      </material>
    </visual>
    <collision>
      <origin xyz="0 0 0" rpy="0 0 0" />
      <geometry>
        <mesh filename="package://assets/meshes/right_ankle_3_3_link.STL" />
      </geometry>
    </collision>
  </link>
  <joint name="right_ankle_3_3_joint" type="revolute">
    <origin
            xyz="0.0236195298410044 -0.435500013525674 0.0352499939525526"
            rpy="3.14159265358978 -1.04719755119661 -3.14159265358978"
        />
    <parent link="right_shin_link" />
    <child link="right_ankle_3_3_link" />
    <axis xyz="0 0 1" />
    <limit lower="-3.14" upper="3.14" effort="2.5" velocity="1" />
  </joint>
  <link name="right_ankle_3_3_cube_link">
    <inertial>
      <origin
                xyz="-2.93355850722321E-09 -0.017007697070905 1.0473990350035E-07"
                rpy="0 0 0"
            />
      <mass value="0.0014193819456622" />
      <inertia
                ixx="2.85047550653734E-08"
                ixy="1.23560655239297E-15"
                ixz="1.97868938301155E-13"
                iyy="3.24387030714847E-08"
                iyz="6.23251109332199E-14"
                izz="3.9186562537098E-08"
            />
    </inertial>
    <visual>
      <origin xyz="0 0 0" rpy="0 0 0" />
      <geometry>
        <mesh
                    filename="package://assets/meshes/right_ankle_3_3_cube_link.STL"
                />
      </geometry>
      <material name="">
        <color rgba="0.792156862745098 0.819607843137255 0.933333333333333 1" />
      </material>
    </visual>
    <collision>
      <origin xyz="0 0 0" rpy="0 0 0" />
      <geometry>
        <mesh
                    filename="package://assets/meshes/right_ankle_3_3_cube_link.STL"
                />
      </geometry>
    </collision>
  </link>
  <joint name="right_ankle_3_3_cube_joint" type="revolute">
    <origin xyz="0 0 0" rpy="0 0 0" />
    <parent link="right_ankle_3_3_link" />
    <child link="right_ankle_3_3_cube_link" />
    <axis xyz="0 -1 0" />
    <limit lower="-3.14" upper="3.14" effort="2.5" velocity="1" />
  </joint>
  <link name="right_ankle_3_3_page_link">
    <inertial>
      <origin
                xyz="-0.000120807831853642 -0.0207078096816969 5.55111512312578E-17"
                rpy="0 0 0"
            />
      <mass value="0.00310095806973405" />
      <inertia
                ixx="6.60738713591306E-07"
                ixy="-1.12233481706694E-09"
                ixz="1.70217018769271E-13"
                iyy="1.07990721626331E-07"
                iyz="1.80552884113031E-21"
                izz="6.98721337032834E-07"
            />
    </inertial>
    <visual>
      <origin xyz="0 0 0" rpy="0 0 0" />
      <geometry>
        <mesh
                    filename="package://assets/meshes/right_ankle_3_3_page_link.STL"
                />
      </geometry>
      <material name="">
        <color rgba="0.792156862745098 0.819607843137255 0.933333333333333 1" />
      </material>
    </visual>
    <collision>
      <origin xyz="0 0 0" rpy="0 0 0" />
      <geometry>
        <mesh
                    filename="package://assets/meshes/right_ankle_3_3_page_link.STL"
                />
      </geometry>
    </collision>
  </link>
  <joint name="right_ankle_3_3_page_joint" type="revolute">
    <origin xyz="0 -0.0199999864743241 0" rpy="0 0 0" />
    <parent link="right_ankle_3_3_cube_link" />
    <child link="right_ankle_3_3_page_link" />
    <axis xyz="1 0 0" />
    <limit lower="-3.14" upper="3.14" effort="2.5" velocity="1" />
  </joint>
  <link name="right_ankle_cube_link">
    <inertial>
      <origin
                xyz="-1.70141678523805E-14 6.8171273071016E-09 6.59194920871187E-16"
                rpy="0 0 0"
            />
      <mass value="0.000189328304341634" />
      <inertia
                ixx="1.15268360237196E-09"
                ixy="-3.15540937575343E-27"
                ixz="-2.14603999802565E-15"
                iyy="1.81031848738357E-09"
                iyz="-3.84731364072346E-26"
                izz="1.15268986006576E-09"
            />
    </inertial>
    <visual>
      <origin xyz="0 0 0" rpy="0 0 0" />
      <geometry>
        <mesh filename="package://assets/meshes/right_ankle_cube_link.STL" />
      </geometry>
      <material name="">
        <color rgba="0.792156862745098 0.819607843137255 0.933333333333333 1" />
      </material>
    </visual>
    <collision>
      <origin xyz="0 0 0" rpy="0 0 0" />
      <geometry>
        <mesh filename="package://assets/meshes/right_ankle_cube_link.STL" />
      </geometry>
    </collision>
  </link>
  <joint name="right_ankle_cube_joint" type="revolute">
    <origin
            xyz="0.00500000000000023 -0.451000010144081 0.0244999999999944"
            rpy="0 0 0"
        />
    <parent link="right_shin_link" />
    <child link="right_ankle_cube_link" />
    <axis xyz="0 0 1" />
    <limit lower="-3.14" upper="3.14" effort="2.5" velocity="1" />
  </joint>
  <link name="right_ankle_axle_link">
    <inertial>
      <origin
                xyz="-6.9218348313152E-05 -0.0250913880795 7.51390485273767E-05"
                rpy="0 0 0"
            />
      <mass value="0.0018856554715005" />
      <inertia
                ixx="3.40888279036599E-07"
                ixy="-5.50460624899203E-14"
                ixz="-1.93998889501307E-10"
                iyy="1.59411270300711E-08"
                iyz="-1.08549831146973E-15"
                izz="3.43002681791167E-07"
            />
    </inertial>
    <visual>
      <origin xyz="0 0 0" rpy="0 0 0" />
      <geometry>
        <mesh filename="package://assets/meshes/right_ankle_axle_link.STL" />
      </geometry>
      <material name="">
        <color rgba="0.792156862745098 0.819607843137255 0.933333333333333 1" />
      </material>
    </visual>
    <collision>
      <origin xyz="0 0 0" rpy="0 0 0" />
      <geometry>
        <mesh filename="package://assets/meshes/right_ankle_axle_link.STL" />
      </geometry>
    </collision>
  </link>
  <joint name="right_ankle_axle_joint" type="revolute">
    <origin xyz="0 0 0" rpy="0 0 0" />
    <parent link="right_ankle_cube_link" />
    <child link="right_ankle_axle_link" />
    <axis xyz="1 0 0" />
    <limit lower="-3.14" upper="3.14" effort="2.5" velocity="1" />
  </joint>
  <link name="right_foot_link">
    <inertial>
      <origin
                xyz="0.000486880895239197 -0.0526281483167862 0.00254809224659175"
                rpy="0 0 0"
            />
      <mass value="0.17435588732169" />
      <inertia
                ixx="0.00031919178724649"
                ixy="-9.15829544129537E-07"
                ixz="-4.43796514247362E-07"
                iyy="0.000287599095065989"
                iyz="-1.68934322698684E-05"
                izz="0.000162719053023517"
            />
    </inertial>
    <visual>
      <origin xyz="0 0 0" rpy="0 0 0" />
      <geometry>
        <mesh filename="package://assets/meshes/right_foot_link.STL" />
      </geometry>
      <material name="">
        <color rgba="0.792156862745098 0.819607843137255 0.933333333333333 1" />
      </material>
    </visual>
    <collision>
      <origin xyz="0 0 0" rpy="0 0 0" />
      <geometry>
        <mesh filename="package://assets/meshes/right_foot_link.STL" />
      </geometry>
    </collision>
  </link>
  <joint name="right_foot_joint" type="revolute">
    <origin xyz="0 -0.019999989834798 0" rpy="0 0 0" />
    <parent link="right_ankle_axle_link" />
    <child link="right_foot_link" />
    <axis xyz="0 -1 0" />
    <limit lower="-3.14" upper="3.14" effort="2.5" velocity="1" />
  </joint>
  <link name="right_toe_link">
    <inertial>
      <origin
                xyz="0.00107157681259222 0.00248698065656139 0.0210804258839141"
                rpy="0 0 0"
            />
      <mass value="0.0528820880759984" />
      <inertia
                ixx="3.25172603856275E-05"
                ixy="-8.81680559569742E-09"
                ixz="-8.51791636512315E-07"
                iyy="5.35541278237666E-05"
                iyz="-3.55674737899477E-07"
                izz="3.36976037536302E-05"
            />
    </inertial>
    <visual>
      <origin xyz="0 0 0" rpy="0 0 0" />
      <geometry>
        <mesh filename="package://assets/meshes/right_toe_link.STL" />
      </geometry>
      <material name="">
        <color rgba="1 1 1 1" />
      </material>
    </visual>
    <collision>
      <origin xyz="0 0 0" rpy="0 0 0" />
      <geometry>
        <mesh filename="package://assets/meshes/right_toe_link.STL" />
      </geometry>
    </collision>
  </link>
  <joint name="right_toe_joint" type="revolute">
    <origin xyz="0 -0.0758129417355203 0.0950624781069581" rpy="0 0 0" />
    <parent link="right_foot_link" />
    <child link="right_toe_link" />
    <axis xyz="1 0 0" />
    <limit lower="-3.14" upper="3.14" effort="8" velocity="1" />
  </joint>
</robot>
